Workbook

Sheet Historical Financials
B1: Model by Brian Githinji
B3: Company name | C3: Carbacid Investments PLc | D3: Ticker | E3: CARB | H3: Fomarting
B4: Share price | C4: 30.9 | D4: Share price date | E4: 46197 | H4: Black text | I4: Historical
B5: Financial Year - Last year ended | C5: 45869 | D5: Model date | E5: 46202 | H5: Blue text | I5: Forecast
B6: Shares Outstanding (Millions) | C6: 254852
B8: Financial year ended | D8: 43830 | E8: =EOMONTH(D8,12) -> 44196 | F8: =EOMONTH(E8,12) -> 44561 | G8: =EOMONTH(F8,12) -> 44926 | H8: =EOMONTH(G8,12) -> 45291 | I8: =EOMONTH(H8,12) -> 45657 | J8: =EOMONTH(I8,12) -> 46022 | K8: =EOMONTH(J8,12) -> 46387 | L8: =EOMONTH(K8,12) -> 46752 | ... O8: =EOMONTH(N8,12) -> 47848
B9: Financial year | D9: =TEXT(D8,"yyyy") -> 2019 | E9: =TEXT(E8,"yyyy") -> 2020 | F9: =TEXT(F8,"yyyy") -> 2021 | G9: =TEXT(G8,"yyyy") -> 2022 | H9: =TEXT(H8,"yyyy") -> 2023 | I9: =TEXT(I8,"yyyy") -> 2024 | J9: =TEXT(J8,"yyyy") -> 2025 | K9: =TEXT(K8,"yyyy") -> 2026 | ... O9: =TEXT(O8,"yyyy") -> 2030 | Q9: 2026 Forecast | R9: 2026 Actual | S9: Actual / Forecast | U9: FY 2025 | V9: HY 2025 | W9: HY 2026 | X9: Y-O-Y | Y9: YTD
B10: Income statement | C10: KShs’m
B11: Revenue | D11: 630500 | E11: 682878 | F11: 906588 | G11: 1414660 | H11: 1720943 | I11: 2066315 | J11: 2099850
B12: Cost of sales | D12: -230231 | E12: -258667 | F12: -352941 | G12: -574483 | H12: -708621 | I12: -846795 | J12: -747182
B13: Gross profit | D13: =D11+D12 -> 400269 | E13: =E11+E12 -> 424211 | F13: =F11+F12 -> 553647 | G13: =G11+G12 -> 840177 | H13: =H11+H12 -> 1012322 | I13: =I11+I12 -> 1219520 | J13: =J11+J12 -> 1352668
B14: Other income | D14: 203666 | E14: 230759 | F14: 240780 | G14: 320988 | H14: 394298 | I14: 354492 | J14: 322516
B15: Fair value gain/(loss) on equity investments | D15: -54938 | E15: -38850 | F15: 12533 | G15: 22674 | H15: 26561 | I15: -31224 | J15: 121234
B16: Fair value gain/(loss) on investment property | D16: 4600 | E16: -2349 | F16: -2591 | G16: 0 | H16: -2420 | I16: -4860 | J16: 0
B17: Impairment Loss | D17: -27 | E17: 0 | F17: 0 | G17: 0 | H17: 0 | I17: 0 | J17: 0
B18: Administrative expenses | D18: -176417 | E18: -186812 | F18: -264104 | G18: -266606 | H18: -333344 | I18: -371054 | J18: -440031
B19: Operating profit | D19: =D13+SUM(D14,D15,D16,D17,D18) -> 377153 | E19: =E13+SUM(E14,E15,E16,E17,E18) -> 426959 | F19: =F13+SUM(F14,F15,F16,F17,F18) -> 540265 | G19: =G13+SUM(G14,G15,G16,G17,G18) -> 917233 | H19: =H13+SUM(H14,H15,H16,H17,H18) -> 1097417 | I19: =I13+SUM(I14,I15,I16,I17,I18) -> 1166874 | J19: =J13+SUM(J14,J15,J16,J17,J18) -> 1356387
B20: Depreciation & amortisation | D20: 54706 | E20: 55115 | F20: 61261 | G20: 72638 | H20: 83875 | I20: 97641 | J20: 154347
B21: Finance income / interest income | D21: 161914 | E21: 186877 | F21: 196289 | G21: 243404 | H21: 255294 | I21: 273469 | J21: 263955
B22: Finance cost | D22: 0 | E22: 0 | F22: 0 | G22: -3404 | H22: -16435 | I22: -43116 | J22: -67823
B23: Profit before tax | D23: =D19+D22 -> 377153 | E23: =E19+E22 -> 426959 | F23: =F19+F22 -> 540265 | G23: =G19+G22 -> 913829 | H23: =H19+H22 -> 1080982 | I23: =I19+I22 -> 1123758 | J23: =J19+J22 -> 1288564
B24: Tax expense | D24: -112564 | E24: -102305 | F24: -125166 | G24: -206165 | H24: -264969 | I24: -280484 | J24: -285650
B25: Profit after tax | D25: =D23+D24 -> 264589 | E25: =E23+E24 -> 324654 | F25: =F23+F24 -> 415099 | G25: =G23+G24 -> 707664 | H25: =H23+H24 -> 816013 | I25: =I23+I24 -> 843274 | J25: =J23+J24 -> 1002914
B26: Basic EPS (KSh) | D26: =D25/D28 -> 1.0382065 | E26: =E25/E28 -> 1.2738923 | F26: =F25/F28 -> 1.6287845 | G26: =G25/G28 -> 2.7767646 | H26: =H25/H28 -> 3.2019093 | I26: =I25/I28 -> 3.3088773 | J26: =J25/J28 -> 3.9352801
B27: DPS declared (KSh) | D27: 0.7 | E27: 0.7 | F27: 1.6 | G27: 1.7 | H27: 1.7 | I27: 1.7 | J27: 2
B28: Shares outstanding ('000) | D28: 254852 | E28: 254852 | F28: 254852 | G28: 254852 | H28: 254852 | I28: 254852 | J28: 254852
B30: Balance Sheet
B31: Cash and cash equivalents | D31: =D82 -> 220036 | E31: =E82 -> 6095 | F31: =F82 -> 167636 | G31: =G82 -> 15251 | H31: =H82 -> 117454 | I31: =I82 -> 524882 | J31: =J82 -> 118576
B32: Short-term bank deposits | D32: 501290 | E32: 813641 | F32: 813115 | G32: 299325 | H32: 254658 | I32: 399676 | J32: 894600
B33: Trade and other receivables | D33: 174741 | E33: 195453 | F33: 213297 | G33: 367176 | H33: 547906 | I33: 581108 | J33: 640533
B34: Inventories | D34: 41236 | E34: 33863 | F34: 39898 | G34: 64954 | H34: 87190 | I34: 140612 | J34: 159475
B35: Current tax recoverable | D35: 3427 | E35: 7274 | F35: 8996 | G35: 9071 | H35: 13706 | I35: 105640 | J35: 0
B36: Other current assets | D36: 15625 | E36: 0 | F36: 0 | G36: 0 | H36: 0 | I36: 0 | J36: 0
B37: Total current assets | D37: =SUM(D31,D32,D33,D34,D35,D36) -> 956355 | E37: =SUM(E31,E32,E33,E34,E35,E36) -> 1056326 | F37: =SUM(F31,F32,F33,F34,F35,F36) -> 1242942 | G37: =SUM(G31,G32,G33,G34,G35,G36) -> 755777 | H37: =SUM(H31,H32,H33,H34,H35,H36) -> 1020914 | I37: =SUM(I31,I32,I33,I34,I35,I36) -> 1751918 | J37: =SUM(J31,J32,J33,J34,J35,J36) -> 1813184
B38: Property, plant and equipment | D38: 919401 | E38: 883728 | F38: 938139 | G38: 994565 | H38: 1360091 | I38: 1963988 | J38: 2221789
B39: Investment property | D39: 249800 | E39: 247451 | F39: 244414 | G39: 299152 | H39: 296732 | I39: 145894 | J39: 222900
B40: Intangible assets | D40: 391 | E40: 346 | F40: 877 | G40: 1528 | H40: 912 | I40: 1853 | J40: 3716
B41: Right-of-use assets / prepaid lease | D41: 52961 | E41: 52672 | F41: 52383 | G41: 52094 | H41: 51805 | I41: 51516 | J41: 51227
B42: Financial assets | D42: 1324593 | E42: 1387308 | F42: 1440469 | G42: 2358631 | H42: 2382670 | I42: 2363154 | J42: 2366872
B43: Total non-current assets | D43: =SUM(D38,D39,D40,D41,D42) -> 2547146 | E43: =SUM(E38,E39,E40,E41,E42) -> 2571505 | F43: =SUM(F38,F39,F40,F41,F42) -> 2676282 | G43: =SUM(G38,G39,G40,G41,G42) -> 3705970 | H43: =SUM(H38,H39,H40,H41,H42) -> 4092210 | I43: =SUM(I38,I39,I40,I41,I42) -> 4526405 | J43: =SUM(J38,J39,J40,J41,J42) -> 4866504
...

Sheet Carbacid Model
B1: Model by Brian Githinji
B2: Carbacid Investments PLC | Industrial + Investment Holding SOTP
B4: Company | C4: Carbacid Investments PLC
B5: NSE Ticker | C5: CARB
B6: Sector | C6: Manufacturing / Industrial Gases
B7: Current Price | C7: =Assumptions_Log!D4 -> 33.1
B8: Target Price | C8: =C200 -> 32.855509
B9: Upside / Downside | C9: =C8/C7-1 -> -0.0073864476
B10: Recommendation | C10: =C203 -> HOLD
B11: Market Capitalisation | C11: =C7*C12 -> 8435.6012
B12: Shares Outstanding | C12: =Assumptions_Log!D6 -> 254.852
B13: Model Date | C13: 46205
C15: Units | D15: 2019A | E15: 2020A | F15: 2021A | G15: 2022A | H15: 2023A | I15: 2024A | J15: 2025A | K15: 2026F | L15: 2027F | M15: 2028F | N15: 2029F | O15: 2030F
B17: KEY ASSUMPTIONS AND FORECAST DRIVERS
B19: CO2 volume growth | C19: % | D19: - | E19: - | F19: - | G19: - | H19: - | I19: - | J19: - | K19: =Assumptions_Log!G$24 -> 0.035 | L19: =Assumptions_Log!H$24 -> 0.04 | M19: =Assumptions_Log!I$24 -> 0.045 | N19: =Assumptions_Log!J$24 -> 0.045 | O19: =Assumptions_Log!K$24 -> 0.04
B20: CO2 price / mix / FX growth | C20: % | D20: - | E20: - | F20: - | G20: - | H20: - | I20: - | J20: - | K20: =Assumptions_Log!G$25 -> 0.015 | L20: =Assumptions_Log!H$25 -> 0.015 | M20: =Assumptions_Log!I$25 -> 0.015 | N20: =Assumptions_Log!J$25 -> 0.015 | O20: =Assumptions_Log!K$25 -> 0.015
B21: Transport/logistics revenue growth | C21: % | D21: - | E21: - | F21: - | G21: - | H21: - | I21: - | J21: - | K21: =Assumptions_Log!G$26 -> 0.07 | L21: =Assumptions_Log!H$26 -> 0.06 | M21: =Assumptions_Log!I$26 -> 0.055 | N21: =Assumptions_Log!J$26 -> 0.05 | O21: =Assumptions_Log!K$26 -> 0.045
B22: Other services growth | C22: % | D22: - | E22: - | F22: - | G22: - | H22: - | I22: - | J22: - | K22: =Assumptions_Log!G$27 -> 0 | L22: =Assumptions_Log!H$27 -> 0 | M22: =Assumptions_Log!I$27 -> 0 | N22: =Assumptions_Log!J$27 -> 0 | O22: =Assumptions_Log!K$27 -> 0
B23: Cost of sales / revenue | C23: % | D23: =IFERROR(-D51/D50,"") -> 0.36515623 | E23: =IFERROR(-E51/E50,"") -> 0.37878948 | F23: =IFERROR(-F51/F50,"") -> 0.38930694 | G23: =IFERROR(-G51/G50,"") -> 0.40609263 | H23: =IFERROR(-H51/H50,"") -> 0.4117632 | I23: =IFERROR(-I51/I50,"") -> 0.40980925 | J23: =IFERROR(-J51/J50,"") -> 0.35582637 | K23: =Assumptions_Log!G$28 -> 0.36 | L23: =Assumptions_Log!H$28 -> 0.37 | M23: =Assumptions_Log!I$28 -> 0.375 | N23: =Assumptions_Log!J$28 -> 0.38 | O23: =Assumptions_Log!K$28 -> 0.38
B24: Gross margin | C24: % | D24: =IFERROR(D53,"") -> 0.63484377 | E24: =IFERROR(E53,"") -> 0.62121052 | F24: =IFERROR(F53,"") -> 0.61069306 | G24: =IFERROR(G53,"") -> 0.59390737 | H24: =IFERROR(H53,"") -> 0.5882368 | I24: =IFERROR(I53,"") -> 0.59019075 | J24: =IFERROR(J53,"") -> 0.64417363 | K24: =1-Assumptions_Log!G$28 -> 0.64 | L24: =1-Assumptions_Log!H$28 -> 0.63 | M24: =1-Assumptions_Log!I$28 -> 0.625 | N24: =1-Assumptions_Log!J$28 -> 0.62 | O24: =1-Assumptions_Log!K$28 -> 0.62
B25: Administrative expenses / revenue | C25: % | D25: =IFERROR(-D54/D50,"") -> 0.27980492 | E25: =IFERROR(-E54/E50,"") -> 0.2735657 | F25: =IFERROR(-F54/F50,"") -> 0.29131645 | G25: =IFERROR(-G54/G50,"") -> 0.18845942 | H25: =IFERROR(-H54/H50,"") -> 0.19369845 | I25: =IFERROR(-I54/I50,"") -> 0.17957281 | J25: =IFERROR(-J54/J50,"") -> 0.20955354 | K25: =Assumptions_Log!G$29 -> 0.21 | L25: =Assumptions_Log!H$29 -> 0.208 | M25: =Assumptions_Log!I$29 -> 0.205 | N25: =Assumptions_Log!J$29 -> 0.203 | O25: =Assumptions_Log!K$29 -> 0.2
B26: D&A / average PPE | C26: % | D26: =IFERROR(D57/AVERAGE(D93,D93),"") -> 0.059501784 | E26: =IFERROR(E57/AVERAGE(D93,E93),"") -> 0.06113262 | F26: =IFERROR(F57/AVERAGE(E93,F93),"") -> 0.067250793 | G26: =IFERROR(G57/AVERAGE(F93,G93),"") -> 0.075167227 | H26: =IFERROR(H57/AVERAGE(G93,H93),"") -> 0.071241829 | I26: =IFERROR(I57/AVERAGE(H93,I93),"") -> 0.058747701 | J26: =IFERROR(J57/AVERAGE(I93,J93),"") -> 0.073748315 | K26: =Assumptions_Log!G$30 -> 0.07 | L26: =Assumptions_Log!H$30 -> 0.07 | M26: =Assumptions_Log!I$30 -> 0.07 | N26: =Assumptions_Log!J$30 -> 0.068 | O26: =Assumptions_Log!K$30 -> 0.068
B27: Capex / revenue | C27: % | D27: =IFERROR(D123/D50,"") -> 0.059773196 | E27: =IFERROR(E123/E50,"") -> 0.073294205 | F27: =IFERROR(F123/F50,"") -> 0.13935878 | G27: =IFERROR(G123/G50,"") -> 0.12810569 | H27: =IFERROR(H123/H50,"") -> 0.27402535 | I27: =IFERROR(I123/I50,"") -> 0.34207127 | J27: =IFERROR(J123/J50,"") -> 0.20484082 | K27: =Assumptions_Log!G$31 -> 0.18 | L27: =Assumptions_Log!H$31 -> 0.1 | M27: =Assumptions_Log!I$31 -> 0.09 | N27: =Assumptions_Log!J$31 -> 0.08 | O27: =Assumptions_Log!K$31 -> 0.08
B28: Receivable days | C28: days | D28: =IFERROR(D89/D50*365,"") -> 101.15855 | E28: =IFERROR(E89/E50*365,"") -> 104.47012 | F28: =IFERROR(F89/F50*365,"") -> 85.875177 | G28: =IFERROR(G89/G50*365,"") -> 94.736007 | H28: =IFERROR(H89/H50*365,"") -> 116.20704 | I28: =IFERROR(I89/I50*365,"") -> 102.64864 | J28: =IFERROR(J89/J50*365,"") -> 111.33869 | K28: =Assumptions_Log!G$32 -> 112 | L28: =Assumptions_Log!H$32 -> 110 | M28: =Assumptions_Log!I$32 -> 108 | N28: =Assumptions_Log!J$32 -> 106 | O28: =Assumptions_Log!K$32 -> 105
B29: Inventory days | C29: days | D29: =IFERROR(D90/(-D51)*365,"") -> 65.374081 | E29: =IFERROR(E90/(-E51)*365,"") -> 47.783424 | F29: =IFERROR(F90/(-F51)*365,"") -> 41.261202 | G29: =IFERROR(G90/(-G51)*365,"") -> 41.268776 | H29: =IFERROR(H90/(-H51)*365,"") -> 44.910255 | I29: =IFERROR(I90/(-I51)*365,"") -> 60.608979 | J29: =IFERROR(J90/(-J51)*365,"") -> 77.903878 | K29: =Assumptions_Log!G$33 -> 75 | L29: =Assumptions_Log!H$33 -> 75 | M29: =Assumptions_Log!I$33 -> 74 | N29: =Assumptions_Log!J$33 -> 74 | O29: =Assumptions_Log!K$33 -> 73
B30: Payable days | C30: days | D30: =IFERROR(D99/(-D51)*365,"") -> 168.71605 | E30: =IFERROR(E99/(-E51)*365,"") -> 159.42813 | F30: =IFERROR(F99/(-F51)*365,"") -> 176.74538 | G30: =IFERROR(G99/(-G51)*365,"") -> 175.29223 | H30: =IFERROR(H99/(-H51)*365,"") -> 199.9261 | I30: =IFERROR(I99/(-I51)*365,"") -> 176.24371 | J30: =IFERROR(J99/(-J51)*365,"") -> 125.8616 | K30: =Assumptions_Log!G$34 -> 126 | L30: =Assumptions_Log!H$34 -> 125 | M30: =Assumptions_Log!I$34 -> 124 | N30: =Assumptions_Log!J$34 -> 123 | O30: =Assumptions_Log!K$34 -> 122
B31: Financial assets growth | C31: % | D31: - | E31: - | F31: - | G31: - | H31: - | I31: - | J31: - | K31: =Assumptions_Log!G$37 -> 0.03 | L31: =Assumptions_Log!H$37 -> 0.03 | M31: =Assumptions_Log!I$37 -> 0.03 | N31: =Assumptions_Log!J$37 -> 0.03 | O31: =Assumptions_Log!K$37 -> 0.03
B32: Investment asset yield | C32: % | D32: - | E32: - | F32: - | G32: - | H32: - | I32: - | J32: - | K32: =Assumptions_Log!G$39 -> 0.08 | L32: =Assumptions_Log!H$39 -> 0.08 | M32: =Assumptions_Log!I$39 -> 0.08 | N32: =Assumptions_Log!J$39 -> 0.08 | O32: =Assumptions_Log!K$39 -> 0.08
B33: Dividend payout ratio | C33: % | D33: =IFERROR(D70/D69,"") -> 0.67423967 | E33: =IFERROR(E70/E69,"") -> 0.549497 | F33: =IFERROR(F70/F69,"") -> 0.98232759 | G33: =IFERROR(G70/G69,"") -> 0.61222332 | H33: =IFERROR(H70/H69,"") -> 0.53093321 | I33: =IFERROR(I70/I69,"") -> 0.51376943 | J33: =IFERROR(J70/J69,"") -> 0.50822304 | K33: =Assumptions_Log!G$40 -> 0.52 | L33: =Assumptions_Log!H$40 -> 0.52 | M33: =Assumptions_Log!I$40 -> 0.52 | N33: =Assumptions_Log!J$40 -> 0.52 | O33: =Assumptions_Log!K$40 -> 0.52
B36: REVENUE BUILD-UP – DRIVER-BASED
B38: CO2 sales revenue | C38: KSh mn | D38: =Segment_Financials!D6 -> 485.907 | E38: =Segment_Financials!E6 -> 536.286 | F38: =Segment_Financials!F6 -> 662.311 | G38: =Segment_Financials!G6 -> 954.771 | H38: =Segment_Financials!H6 -> 1082.416 | I38: =Segment_Financials!I6 -> 1340.801 | J38: =Segment_Financials!J6 -> 1314.242 | K38: =J38*(1+K19+K20) -> 1379.9541 | L38: =K38*(1+L19+L20) -> 1455.8516 | M38: =L38*(1+M19+M20) -> 1543.2027 | N38: =M38*(1+N19+N20) -> 1635.7948 | O38: =N38*(1+O19+O20) -> 1725.7635
B39: Transport / logistics revenue | C39: KSh mn | D39: =Segment_Financials!D7 -> 144.593 | E39: =Segment_Financials!E7 -> 146.592 | F39: =Segment_Financials!F7 -> 244.277 | G39: =Segment_Financials!G7 -> 459.889 | H39: =Segment_Financials!H7 -> 638.527 | I39: =Segment_Financials!I7 -> 725.514 | J39: =Segment_Financials!J7 -> 785.608 | K39: =J39*(1+K21) -> 840.60056 | L39: =K39*(1+L21) -> 891.03659 | M39: =L39*(1+M21) -> 940.04361 | N39: =M39*(1+N21) -> 987.04579 | O39: =N39*(1+O21) -> 1031.4628
B40: Other operating revenue / services | C40: KSh mn | D40: =Segment_Financials!D8 -> 0 | E40: =Segment_Financials!E8 -> 0 | F40: =Segment_Financials!F8 -> 0 | G40: =Segment_Financials!G8 -> 0 | H40: =Segment_Financials!H8 -> 0 | I40: =Segment_Financials!I8 -> 0 | J40: =Segment_Financials!J8 -> 0 | K40: =J40*(1+K22) -> 0 | L40: =K40*(1+L22) -> 0 | M40: =L40*(1+M22) -> 0 | N40: =M40*(1+N22) -> 0 | O40: =N40*(1+O22) -> 0
B41: Total operating revenue | C41: KSh mn | D41: =SUM(D38:D40) -> 630.5 | E41: =SUM(E38:E40) -> 682.878 | F41: =SUM(F38:F40) -> 906.588 | G41: =SUM(G38:G40) -> 1414.66 | H41: =SUM(H38:H40) -> 1720.943 | I41: =SUM(I38:I40) -> 2066.315 | J41: =SUM(J38:J40) -> 2099.85 | K41: =SUM(K38:K40) -> 2220.5547 | ... O41: =SUM(O38:O40) -> 2757.2264
B42: Revenue growth | C42: % | D42: - | E42: =IFERROR(E41/D41-1,"") -> 0.083073751 | F42: =IFERROR(F41/E41-1,"") -> 0.32759878 | G42: =IFERROR(G41/F41-1,"") -> 0.56042215 | H42: =IFERROR(H41/G41-1,"") -> 0.21650644 | I42: =IFERROR(I41/H41-1,"") -> 0.20068765 | J42: =IFERROR(J41/I41-1,"") -> 0.016229375 | K42: =IFERROR(K41/J41-1,"") -> 0.057482515 | L42: =IFERROR(L41/K41-1,"") -> 0.056892772 | ... O42: =IFERROR(O41/N41-1,"") -> 0.05123673
B43: CO2 sales growth | C43: % | D43: - | E43: =IFERROR(E38/D38-1,"") -> 0.10368033 | F43: =IFERROR(F38/E38-1,"") -> 0.23499588 | G43: =IFERROR(G38/F38-1,"") -> 0.44157503 | H43: =IFERROR(H38/G38-1,"") -> 0.13369174 | I43: =IFERROR(I38/H38-1,"") -> 0.23871136 | J43: =IFERROR(J38/I38-1,"") -> -0.019808309 | K43: =IFERROR(K38/J38-1,"") -> 0.05 | L43: =IFERROR(L38/K38-1,"") -> 0.055 | ... O43: =IFERROR(O38/N38-1,"") -> 0.055
B44: Transport/logistics growth | C44: % | D44: - | E44: =IFERROR(E39/D39-1,"") -> 0.013825012 | F44: =IFERROR(F39/E39-1,"") -> 0.66637334 | G44: =IFERROR(G39/F39-1,"") -> 0.88265371 | H44: =IFERROR(H39/G39-1,"") -> 0.38843721 | I44: =IFERROR(I39/H39-1,"") -> 0.13623073 | J44: =IFERROR(J39/I39-1,"") -> 0.082829553 | K44: =IFERROR(K39/J39-1,"") -> 0.07 | L44: =IFERROR(L39/K39-1,"") -> 0.06 | ... O44: =IFERROR(O39/N39-1,"") -> 0.045
B48: INCOME STATEMENT – OPERATING VS INVESTMENT SPLIT
B50: Revenue | C50: KSh mn | D50: ='Historical Financials'!D11/1000 -> 630.5 | E50: ='Historical Financials'!E11/1000 -> 682.878 | F50: ='Historical Financials'!F11/1000 -> 906.588 | G50: ='Historical Financials'!G11/1000 -> 1414.66 | H50: ='Historical Financials'!H11/1000 -> 1720.943 | I50: ='Historical Financials'!I11/1000 -> 2066.315 | J50: ='Historical Financials'!J11/1000 -> 2099.85 | K50: =K41 -> 2220.5547 | L50: =L41 -> 2346.8882 | M50: =M41 -> 2483.2463 | N50: =N41 -> 2622.8406 | O50: =O41 -> 2757.2264
B51: Cost of sales | C51: KSh mn | D51: ='Historical Financials'!D12/1000 -> -230.231 | E51: ='Historical Financials'!E12/1000 -> -258.667 | F51: ='Historical Financials'!F12/1000 -> -352.941 | G51: ='Historical Financials'!G12/1000 -> -574.483 | H51: ='Historical Financials'!H12/1000 -> -708.621 | I51: ='Historical Financials'!I12/1000 -> -846.795 | J51: ='Historical Financials'!J12/1000 -> -747.182 | K51: =-K50*K23 -> -799.39968 | L51: =-L50*L23 -> -868.34862 | M51: =-M50*M23 -> -931.21735 | N51: =-N50*N23 -> -996.67943 | O51: =-O50*O23 -> -1047.746
...

Sheet Assumptions_Log
B1: Carbacid Investments PLC – Assumptions Log
B3: Category | C3: Assumption | D3: Base / Value | E3: Unit | F3: Source / Rationale | G3: FY2026F | H3: FY2027F | I3: FY2028F | J3: FY2029F | K3: FY2030F
B4: Market | C4: Current share price | D4: 33.1 | E4: KSh/share | F4: MarketScreener / NSE end-of-day quote, 01-Jul-2026
B5: Market | C5: Share price date | D5: 2026-07-01 | E5: date | F5: Source: MarketScreener quote snapshot
B6: Market | C6: Shares outstanding | D6: 254.852 | E6: mn shares | F6: Linked to Historical Financials / 2025 AR share count
B7: Valuation | C7: Risk-free rate | D7: 0.1232 | E7: % | F7: Kenya 10Y government bond yield, 01-Jul-2026
B8: Valuation | C8: Beta | D8: 0.65 | E8: x | F8: Small-cap industrial / specialty gas adjusted beta
B9: Valuation | C9: Equity risk premium | D9: 0.045 | E9: % | F9: Kenya / frontier market equity risk premium assumption
B10: Valuation | C10: Cost of equity | D10: =D7+D8*D9 -> 0.15245 | E10: % | F10: CAPM
B11: Valuation | C11: Pre-tax cost of debt | D11: 0.12 | E11: % | F11: Normalised local/FX borrowing cost; anchored to FY2024 loan note disclosure
B12: Valuation | C12: Tax rate | D12: 0.23 | E12: % | F12: Normalised cash tax rate based on recent effective tax rates
B13: Valuation | C13: Target debt weight | D13: 0.09 | E13: % | F13: Conservative long-run capital structure assumption
B14: Valuation | C14: WACC | D14: =D10*(1-D13)+D11*(1-D12)*D13 -> 0.1470455 | E14: % | F14: WACC = CoE x E/V + after-tax CoD x D/V
B15: Valuation | C15: Terminal growth | D15: 0.05 | E15: % | F15: Long-run nominal growth assumption
B16: Valuation | C16: DCF / SOTP weight | D16: 0.65 | E16: % | F16: Primary method; separates operating value and non-operating investments
B17: Valuation | C17: EV/EBITDA weight | D17: 0.2 | E17: % | F17: Operating multiple cross-check
B18: Valuation | C18: P/E weight | D18: 0.15 | E18: % | F18: Earnings cross-check; lower weight due investment-income volatility
B19: Valuation | C19: EV/EBITDA exit multiple | D19: 6 | E19: x | F19: Specialty industrial / gas multiple cross-check
B20: Valuation | C20: P/E exit multiple | D20: 10 | E20: x | F20: Market earnings multiple sanity check
B21: Revenue Mix | C21: CO2 sales mix of revenue | D21: =Segment_Financials!J12 -> 0.62587423 | E21: % | F21: Calculated from Note 6: CO2 sales / total operating revenue
B22: Revenue Mix | C22: Transport revenue mix | D22: =Segment_Financials!J13 -> 0.37412577 | E22: % | F22: Calculated from Note 6: transport revenue / total operating revenue
B23: Revenue Mix | C23: Other services revenue mix | D23: =1-D21-D22 -> 0 | E23: % | F23: Calculated residual from Note 6; no other operating revenue separately disclosed
B24: Forecast Driver | C24: CO2 volume growth | E24: % | F24: Calculated from Note 6 CO2 sales history, moderated for FY2025 FX drag and new market expansion | G24: 0.035 | H24: 0.04 | I24: 0.045 | J24: 0.045 | K24: 0.04
B25: Forecast Driver | C25: CO2 price / mix / FX | E25: % | F25: Calculated from Note 5 export mix / Note 6 sales mix; allows pricing, mix and FX effect | G25: 0.015 | H25: 0.015 | I25: 0.015 | J25: 0.015 | K25: 0.015
B26: Forecast Driver | C26: Transport/logistics growth | E26: % | F26: Calculated from Note 6 transport revenue history; tapered to reflect mature export logistics base | G26: 0.07 | H26: 0.06 | I26: 0.055 | J26: 0.05 | K26: 0.045
B27: Forecast Driver | C27: Other services growth | E27: % | F27: No separate other operating revenue disclosed in Note 6; set to 0% | G27: 0 | H27: 0 | I27: 0 | J27: 0 | K27: 0
B28: Forecast Driver | C28: Cost of sales / revenue | E28: % | F28: Royalty, power, fuel, labour and maintenance assumptions | G28: 0.36 | H28: 0.37 | I28: 0.375 | J28: 0.38 | K28: 0.38
B29: Forecast Driver | C29: Administrative expenses / revenue | E29: % | F29: Fixed-cost absorption offset by regional expansion | G29: 0.21 | H29: 0.208 | I29: 0.205 | J29: 0.203 | K29: 0.2
B30: Forecast Driver | C30: D&A / average PPE | E30: % | F30: PPE depreciation intensity | G30: 0.07 | H30: 0.07 | I30: 0.07 | J30: 0.068 | K30: 0.068
B31: Forecast Driver | C31: Capex / revenue | E31: % | F31: Solar expansion / fleet / plant maintenance | G31: 0.18 | H31: 0.1 | I31: 0.09 | J31: 0.08 | K31: 0.08
B32: Forecast Driver | C32: Receivable days | E32: days | F32: Historical collection cycle adjusted for export mix | G32: 112 | H32: 110 | I32: 108 | J32: 106 | K32: 105
B33: Forecast Driver | C33: Inventory days | E33: days | F33: Gas inventory and spares inventory cycle | G33: 75 | H33: 75 | I33: 74 | J33: 74 | K33: 73
B34: Forecast Driver | C34: Payable days | E34: days | F34: Supplier/royalty payment cycle | G34: 126 | H34: 125 | I34: 124 | J34: 123 | K34: 122
B35: Forecast Driver | C35: Other current assets / revenue | E35: % | F35: Small operating accruals | G35: 0.005 | H35: 0.005 | I35: 0.005 | J35: 0.005 | K35: 0.005
... B40: Capital Return | C40: Dividend payout ratio | E40: % | F40: Consistent dividend payout, with reinvestment for growth | G40: 0.52 | H40: 0.52 | I40: 0.52 | J40: 0.52 | K40: 0.52

Sheet Segment_Financials
B1: Carbacid Investments PLC – Segment Financials from Annual Reports
C3: Units | D3: 2019A | E3: 2020A | F3: 2021A | G3: 2022A | H3: 2023A | I3: 2024A | J3: 2025A | K3: 2026F | L3: 2027F | M3: 2028F | N3: 2029F | O3: 2030F
B5: REVENUE SPLIT – NOTE 6 ACTUALS / FORECAST
B6: CO2 sales revenue | C6: KSh mn | D6: 485.907 | E6: 536.286 | F6: 662.311 | G6: 954.771 | H6: 1082.416 | I6: 1340.801 | J6: 1314.242 | K6: ='Carbacid Model'!K38 -> 1379.9541 | L6: ='Carbacid Model'!L38 -> 1455.8516 | M6: ='Carbacid Model'!M38 -> 1543.2027 | N6: ='Carbacid Model'!N38 -> 1635.7948 | O6: ='Carbacid Model'!O38 -> 1725.7635
B7: Transport revenue | C7: KSh mn | D7: 144.593 | E7: 146.592 | F7: 244.277 | G7: 459.889 | H7: 638.527 | I7: 725.514 | J7: 785.608 | K7: ='Carbacid Model'!K39 -> 840.60056 | L7: ='Carbacid Model'!L39 -> 891.03659 | M7: ='Carbacid Model'!M39 -> 940.04361 | N7: ='Carbacid Model'!N39 -> 987.04579 | O7: ='Carbacid Model'!O39 -> 1031.4628
B8: Other operating revenue / services | C8: KSh mn | D8: 0 | E8: 0 | F8: 0 | G8: 0 | H8: 0 | I8: 0 | J8: 0 | K8: ='Carbacid Model'!K40 -> 0 | L8: ='Carbacid Model'!L40 -> 0 | M8: ='Carbacid Model'!M40 -> 0 | N8: ='Carbacid Model'!N40 -> 0 | O8: ='Carbacid Model'!O40 -> 0
B9: Total operating revenue | C9: KSh mn | D9: =SUM(D6:D8) -> 630.5 | E9: =SUM(E6:E8) -> 682.878 | F9: =SUM(F6:F8) -> 906.588 | G9: =SUM(G6:G8) -> 1414.66 | H9: =SUM(H6:H8) -> 1720.943 | I9: =SUM(I6:I8) -> 2066.315 | J9: =SUM(J6:J8) -> 2099.85 | K9: ='Carbacid Model'!K41 -> 2220.5547 | L9: ='Carbacid Model'!L41 -> 2346.8882 | M9: ='Carbacid Model'!M41 -> 2483.2463 | N9: ='Carbacid Model'!N41 -> 2622.8406 | O9: ='Carbacid Model'!O41 -> 2757.2264
B10: CO2 sales growth | C10: % | D10: ="" | E10: =IFERROR(E6/D6-1,"") -> 0.10368033 | F10: =IFERROR(F6/E6-1,"") -> 0.23499588 | G10: =IFERROR(G6/F6-1,"") -> 0.44157503 | H10: =IFERROR(H6/G6-1,"") -> 0.13369174 | I10: =IFERROR(I6/H6-1,"") -> 0.23871136 | J10: =IFERROR(J6/I6-1,"") -> -0.019808309 | K10: =IFERROR(K6/J6-1,"") -> 0.05 | L10: =IFERROR(L6/K6-1,"") -> 0.055 | ... O10: =IFERROR(O6/N6-1,"") -> 0.055
B11: Transport revenue growth | C11: % | D11: ="" | E11: =IFERROR(E7/D7-1,"") -> 0.013825012 | F11: =IFERROR(F7/E7-1,"") -> 0.66637334 | G11: =IFERROR(G7/F7-1,"") -> 0.88265371 | H11: =IFERROR(H7/G7-1,"") -> 0.38843721 | I11: =IFERROR(I7/H7-1,"") -> 0.13623073 | J11: =IFERROR(J7/I7-1,"") -> 0.082829553 | K11: =IFERROR(K7/J7-1,"") -> 0.07 | L11: =IFERROR(L7/K7-1,"") -> 0.06 | ... O11: =IFERROR(O7/N7-1,"") -> 0.045
B12: CO2 revenue mix | C12: % | D12: =IFERROR(D6/D9,"") -> 0.77066931 | E12: =IFERROR(E6/E9,"") -> 0.78533208 | F12: =IFERROR(F6/F9,"") -> 0.73055346 | G12: =IFERROR(G6/G9,"") -> 0.67491199 | H12: =IFERROR(H6/H9,"") -> 0.62896679 | I12: =IFERROR(I6/I9,"") -> 0.64888509 | J12: =IFERROR(J6/J9,"") -> 0.62587423 | K12: =IFERROR(K6/K9,"") -> 0.62144568 | ... O12: =IFERROR(O6/O9,"") -> 0.62590564
B13: Transport revenue mix | C13: % | D13: =IFERROR(D7/D9,"") -> 0.22933069 | E13: =IFERROR(E7/E9,"") -> 0.21466792 | F13: =IFERROR(F7/F9,"") -> 0.26944654 | G13: =IFERROR(G7/G9,"") -> 0.32508801 | H13: =IFERROR(H7/H9,"") -> 0.37103321 | I13: =IFERROR(I7/I9,"") -> 0.35111491 | J13: =IFERROR(J7/J9,"") -> 0.37412577 | K13: =IFERROR(K7/K9,"") -> 0.37855432 | ... O13: =IFERROR(O7/O9,"") -> 0.37409436
B14: Domestic sales | C14: KSh mn | D14: 371.283 | E14: 464.405 | F14: 437.065 | G14: 422.215 | H14: 394.023 | I14: 501.652 | J14: 613.397 | K14: =K9-K15 -> 688.37194 | L14: =L9-L15 -> 751.00421 | M14: =M9-M15 -> 819.47127 | N14: =N9-N15 -> 891.76581 | O14: =O9-O15 -> 965.02924
B15: Export sales | C15: KSh mn | D15: 259.217 | E15: 218.473 | F15: 469.523 | G15: 992.445 | H15: 1326.92 | I15: 1564.663 | J15: 1486.453 | K15: =K9*K16 -> 1532.1827 | L15: =L9*L16 -> 1595.884 | M15: =M9*M16 -> 1663.775 | N15: =N9*N16 -> 1731.0748 | O15: =O9*O16 -> 1792.1972
B16: Export revenue mix | C16: % | D16: =IFERROR(D15/D9,"") -> 0.41112926 | E16: =IFERROR(E15/E9,"") -> 0.31992977 | F16: =IFERROR(F15/F9,"") -> 0.51790119 | G16: =IFERROR(G15/G9,"") -> 0.70154313 | H16: =IFERROR(H15/H9,"") -> 0.77104239 | I16: =IFERROR(I15/I9,"") -> 0.75722385 | J16: =IFERROR(J15/J9,"") -> 0.70788533 | K16: 0.69 | L16: 0.68 | M16: 0.67 | N16: 0.66 | O16: 0.65
B18: SEGMENT RESULTS – NOTE 5 ACTUALS / FORECAST
B19: Trading revenue from contracts with customers | C19: KSh mn | D19: 630.5 | E19: 682.878 | F19: 906.588 | G19: 1414.66 | H19: 1720.943 | I19: 2066.315 | J19: 2099.85 | K19: ='Carbacid Model'!K41 -> 2220.5547 | L19: ='Carbacid Model'!L41 -> 2346.8882 | M19: ='Carbacid Model'!M41 -> 2483.2463 | N19: ='Carbacid Model'!N41 -> 2622.8406 | O19: ='Carbacid Model'!O41 -> 2757.2264
B20: Investment revenue from contracts with customers | C20: KSh mn | D20: 0 | E20: 0 | F20: 0 | G20: 0 | H20: 0 | I20: 0 | J20: 0 | K20: 0 | L20: 0 | M20: 0 | N20: 0 | O20: 0
B21: Trading interest income | C21: KSh mn | D21: 1.979 | E21: 0.036 | F21: 0.001 | G21: 0.985 | H21: 0.791 | I21: 1.373 | J21: 3.196 | K21: ='Carbacid Model'!K60*0.01 -> 1.8934976 | L21: ='Carbacid Model'!L60*0.01 -> 1.9503025 | M21: ='Carbacid Model'!M60*0.01 -> 2.0088116 | N21: ='Carbacid Model'!N60*0.01 -> 2.069076 | O21: ='Carbacid Model'!O60*0.01 -> 2.1311482
B22: Investment interest income | C22: KSh mn | D22: 159.935 | E22: 186.841 | F22: 196.289 | G22: 242.419 | H22: 254.503 | I22: 272.096 | J22: 260.759 | K22: ='Carbacid Model'!K60-K21 -> 187.45626 | L22: ='Carbacid Model'!L60-L21 -> 193.07995 | M22: ='Carbacid Model'!M60-M21 -> 198.87235 | N22: ='Carbacid Model'!N60-N21 -> 204.83852 | O22: ='Carbacid Model'!O60-O21 -> 210.98367
B23: Fair value gain/(loss) on investment property | C23: KSh mn | D23: 4.6 | E23: -2.349 | F23: -2.591 | G23: 0 | H23: -2.489 | I23: -4.86 | J23: 0 | K23: 0 | L23: 0 | M23: 0 | N23: 0 | O23: 0
B24: Trading profit before tax | C24: KSh mn | D24: 247.783 | E24: 264.702 | F24: 352.96 | G24: 620.684 | H24: 764.671 | I24: 867.202 | J24: 915.707 | K24: ='Carbacid Model'!K55+K21 -> 956.732 | L24: ='Carbacid Model'!L55+L21 -> 992.33711 | M24: ='Carbacid Model'!M55+M21 -> 1044.9722 | N24: ='Carbacid Model'!N55+N21 -> 1095.7936 | O24: ='Carbacid Model'!O55+O21 -> 1160.1662
B25: Investment profit before tax | C25: KSh mn | D25: 129.37 | E25: 162.257 | F25: 187.305 | G25: 293.145 | H25: 316.445 | I25: 256.556 | J25: 372.857 | K25: ='Carbacid Model'!K64-K24 -> 98.84714 | L25: ='Carbacid Model'!L64-L24 -> 113.33174 | M25: ='Carbacid Model'!M64-M24 -> 127.09896 | N25: ='Carbacid Model'!N64-N24 -> 140.24247 | O25: ='Carbacid Model'!O64-O24 -> 152.84723
B26: Group profit before tax | C26: KSh mn | D26: 377.153 | E26: 426.959 | F26: 540.265 | G26: 913.829 | H26: 1080.982 | I26: 1123.758 | J26: 1288.564 | K26: ='Carbacid Model'!K64 -> 1055.5791 | L26: ='Carbacid Model'!L64 -> 1105.6689 | M26: ='Carbacid Model'!M64 -> 1172.0712 | N26: ='Carbacid Model'!N64 -> 1236.0361 | O26: ='Carbacid Model'!O64 -> 1313.0135
B27: Trading PBT margin | C27: % | D27: =IFERROR(D24/D19,"") -> 0.39299445 | E27: =IFERROR(E24/E19,"") -> 0.38762707 | F27: =IFERROR(F24/F19,"") -> 0.3893279 | G27: =IFERROR(G24/G19,"") -> 0.43875136 | H27: =IFERROR(H24/H19,"") -> 0.44433255 | I27: =IFERROR(I24/I19,"") -> 0.41968529 | J27: =IFERROR(J24/J19,"") -> 0.4360821 | K27: =IFERROR(K24/K19,"") -> 0.43085271 | ... O27: =IFERROR(O24/O19,"") -> 0.42077293
B28: Investment PBT / investment assets | C28: % | D28: =IFERROR(D25/D32,"") -> 0.054493973 | E28: =IFERROR(E25/E32,"") -> 0.072854129 | F28: =IFERROR(F25/F32,"") -> 0.073941331 | G28: =IFERROR(G25/G32,"") -> 0.093607204 | H28: =IFERROR(H25/H32,"") -> 0.089543771 | I28: =IFERROR(I25/I32,"") -> 0.052317069 | J28: =IFERROR(J25/J32,"") -> 0.067349366 | K28: =IFERROR(K25/K32,"") -> 0.011594472 | ... O28: =IFERROR(O25/O32,"") -> 0.016803704
B30: SEGMENT ASSETS AND LIABILITIES – NOTE 5 ACTUALS
B31: Trading segment assets | C31: KSh mn | D31: 1129.478 | E31: 1400.682 | F31: 1386.067 | G31: 1329.533 | H31: 1978.573 | I31: 3216.495 | J31: 3268.685 | K31: ='Carbacid Model'!K93+'Carbacid Model'!K89+'Carbacid Model'!K90+'Carbacid Model'!K92 -> 5219.5724 | L31: ='Carbacid Model'!L93+'Carbacid Model'!L89+'Carbacid Model'!L90+'Carbacid Model'!L92 -> 5562.2989 | M31: ='Carbacid Model'!M93+'Carbacid Model'!M89+'Carbacid Model'!M90+'Carbacid Model'!M92 -> 5931.7386 | N31: ='Carbacid Model'!N93+'Carbacid Model'!N89+'Carbacid Model'!N90+'Carbacid Model'!N92 -> 6331.7818 | O31: ='Carbacid Model'!O93+'Carbacid Model'!O89+'Carbacid Model'!O90+'Carbacid Model'!O92 -> 6758.3214
B32: Investment segment assets | C32: KSh mn | D32: 2374.024 | E32: 2227.149 | F32: 2533.157 | G32: 3131.65 | H32: 3533.97 | I32: 4903.868 | J32: 5536.162 | K32: ='Carbacid Model'!K88+'Carbacid Model'!K96+'Carbacid Model'!K97+'Carbacid Model'!K101 -> 8525.368 | L32: ='Carbacid Model'!L88+'Carbacid Model'!L96+'Carbacid Model'!L97+'Carbacid Model'!L101 -> 8678.1377 | M32: ='Carbacid Model'!M88+'Carbacid Model'!M96+'Carbacid Model'!M97+'Carbacid Model'!M101 -> 8819.7518 | N32: ='Carbacid Model'!N88+'Carbacid Model'!N96+'Carbacid Model'!N97+'Carbacid Model'!N101 -> 8951.8777 | O32: ='Carbacid Model'!O88+'Carbacid Model'!O96+'Carbacid Model'!O97+'Carbacid Model'!O101 -> 9096.0437
B33: Group segment assets | C33: KSh mn | D33: 3503.501 | E33: 3627.831 | F33: 3919.224 | G33: 4461.183 | H33: 5512.543 | I33: 8120.363 | J33: 8804.847 | K33: =K31+K32 -> 13744.94 | L33: =L31+L32 -> 14240.437 | M33: =M31+M32 -> 14751.49 | N33: =N31+N32 -> 15283.659 | O33: =O31+O32 -> 15854.365
B34: Trading segment liabilities | C34: KSh mn | D34: 323.403 | E34: 314.5 | F34: 164.384 | G34: 593.809 | H34: 795.504 | I34: 2797.818 | J34: 2804.285 | K34: ='Carbacid Model'!K99+'Carbacid Model'!K102+'Carbacid Model'!K105 -> 975.50285 | L34: ='Carbacid Model'!L99+'Carbacid Model'!L102+'Carbacid Model'!L105 -> 926.9708 | M34: ='Carbacid Model'!M99+'Carbacid Model'!M102+'Carbacid Model'!M105 -> 882.99079 | N34: ='Carbacid Model'!N99+'Carbacid Model'!N102+'Carbacid Model'!N105 -> 845.83613 | O34: ='Carbacid Model'!O99+'Carbacid Model'!O102+'Carbacid Model'!O105 -> 809.17746
B35: Investment segment liabilities | C35: KSh mn | D35: 52.607 | E35: 61.235 | F35: 266.041 | G35: 38.477 | H35: 321.362 | I35: 351.703 | J35: 451.051 | K35: ='Carbacid Model'!K100+'Carbacid Model'!K103 -> 173.35296 | L35: ='Carbacid Model'!L100+'Carbacid Model'!L103 -> 182.41749 | M35: ='Carbacid Model'!M100+'Carbacid Model'!M103 -> 193.18931 | N35: ='Carbacid Model'!N100+'Carbacid Model'!N103 -> 203.89539 | O35: ='Carbacid Model'!O100+'Carbacid Model'!O103 -> 215.43517
B36: Group segment liabilities | C36: KSh mn | D36: 376.009 | E36: 375.735 | F36: 430.425 | G36: 632.286 | H36: 1116.866 | I36: 3149.521 | J36: 3255.336 | K36: =K34+K35 -> 1148.8558 | L36: =L34+L35 -> 1109.3883 | M36: =M34+M35 -> 1076.1801 | N36: =N34+N35 -> 1049.7315 | O36: =O34+O35 -> 1024.6126
B38: SEGMENT SUPPORTING ITEMS – NOTE 5 / NOTE 9 ACTUALS
B39: Tax expense – Trading | C39: KSh mn | D39: -77.31 | E39: -78.44 | F39: -100.804 | G39: -188.297 | H39: -228.214 | I39: -252.529 | J39: -273.876 | K39: ='Carbacid Model'!K65*K27 -> -104.6038 | L39: ='Carbacid Model'!L65*L27 -> -107.52755 | M39: ='Carbacid Model'!M65*M27 -> -113.44015 | N39: ='Carbacid Model'!N65*N27 -> -118.77249 | O39: ='Carbacid Model'!O65*O27 -> -127.07052
B40: Tax expense – Investment | C40: KSh mn | D40: -35.254 | E40: -23.865 | F40: -24.362 | G40: -17.868 | H40: -36.755 | I40: -27.955 | J40: -11.774 | K40: ='Carbacid Model'!K65-K39 -> -138.1794 | L40: ='Carbacid Model'!L65-L39 -> -146.77629 | M40: ='Carbacid Model'!M65-M39 -> -156.13623 | N40: ='Carbacid Model'!N65-N39 -> -165.51581 | O40: ='Carbacid Model'!O65-O39 -> -174.92258
B41: Tax expense – Group | C41: KSh mn | D41: -112.564 | E41: -102.305 | F41: -125.166 | G41: -206.165 | H41: -264.969 | I41: -280.484 | J41: -285.65 | K41: ='Carbacid Model'!K65 -> -242.7832 | L41: ='Carbacid Model'!L65 -> -254.30384 | M41: ='Carbacid Model'!M65 -> -269.57638 | N41: ='Carbacid Model'!N65 -> -284.2883 | O41: ='Carbacid Model'!O65 -> -301.9931
B42: Depreciation PPE – Trading | C42: KSh mn | D42: 53.574 | E42: 54.587 | F42: 60.717 | G42: 69.025 | H42: 82.936 | I42: 97.047 | J42: 152.663 | K42: ='Carbacid Model'!K57 -> 155.52523 | L42: ='Carbacid Model'!L57 -> 172.61745 | M42: ='Carbacid Model'!M57 -> 176.96245 | N42: ='Carbacid Model'!N57 -> 175.0704 | O42: ='Carbacid Model'!O57 -> 177.43386
B43: Depreciation PPE – Investment | C43: KSh mn | D43: 0 | E43: 0 | F43: 0 | G43: 2.708 | H43: 0.034 | I43: 0.034 | J43: 0.034 | K43: 0 | L43: 0 | M43: 0 | N43: 0 | O43: 0
B44: Depreciation PPE – Group | C44: KSh mn | D44: 53.574 | E44: 54.587 | F44: 60.717 | G44: 71.733 | H44: 82.97 | I44: 97.081 | J44: 152.697 | K44: =K42+K43 -> 155.52523 | L44: =L42+L43 -> 172.61745 | M44: =M42+M43 -> 176.96245 | N44: =N42+N43 -> 175.0704 | O44: =O42+O43 -> 177.43386
B45: Amortisation of intangible assets | C45: KSh mn | D45: 0.179 | E45: 0.239 | F45: 0.239 | G45: 0.616 | H45: 0.616 | I45: 0.271 | J45: 1.361 | K45: 0 | L45: 0 | M45: 0 | N45: 0 | O45: 0
...

Sheet Valuation_Summary
B1: Carbacid Investments PLC – Valuation Summary
B3: Valuation method | C3: Weight | D3: Fair value / share | E3: Comment
B4: FCFF DCF / SOTP | C4: ='Carbacid Model'!C197 -> 0.65 | D4: ='Carbacid Model'!C192 -> 37.652874 | E4: Primary method; operating value + separate non-operating assets
B5: EV/EBITDA | C5: ='Carbacid Model'!C198 -> 0.2 | D5: ='Carbacid Model'!C194 -> 26.921628 | E5: Industrial / specialty gas cross-check
B6: P/E | C6: ='Carbacid Model'!C199 -> 0.15 | D6: ='Carbacid Model'!C196 -> 19.978765 | E6: Earnings cross-check; lowest weight due investment income volatility
B8: Weighted target price | C8: ='Carbacid Model'!C200 -> 32.855509
B9: Current price | C9: ='Carbacid Model'!C201 -> 33.1
B10: Upside / downside | C10: ='Carbacid Model'!C202 -> -0.0073864476
B11: Recommendation | C11: ='Carbacid Model'!C203 -> HOLD
B12: Market capitalisation at target | C12: ='Carbacid Model'!C200*Assumptions_Log!D6 -> 8373.2921
B13: Model date | C13: 46205
B14: Methodology | C14: Industrial SOTP: FCFF operating value + non-operating investments; DDM not used.
B17: Judgement | C17: Use SOTP because Carbacid combines an operating CO₂ business and an investment portfolio. Reported PAT includes investment income and fair-value movements, so operating cash flow is valued separately from non-operating assets.
B18: Revenue logic | C18: Revenue is split using actual Note 6 disclosures: CO2 sales revenue and transport revenue. Other operating services are set to zero unless disclosed in future reports.
B19: Gross margin logic | C19: FY2025 margin benefits from solar power and plant efficiency, but royalty, labour, maintenance and fuel costs are expected to create partial mean reversion.
B20: Investment portfolio | C20: Cash/deposits, financial assets and investment property are added separately at latest actual book/fair value to avoid double-counting.
B21: Recommendation rule | C21: BUY >15% upside; SELL <-10% downside; otherwise HOLD.

Sheet Sensitivity
B1: Carbacid Investments PLC – Sensitivity Analysis
B3: DCF/SOTP Sensitivity: Target Price vs WACC and Terminal Growth
B4: Terminal g \ WACC | C4: 0.13 | D4: 0.14 | E4: 0.15 | F4: 0.16 | G4: 0.17 | H4: 0.18
B5: 0.03 | C5: =((('Carbacid Model'!$K$156/(1+C$4))+('Carbacid Model'!$L$156/(1+C$4)^2)+('Carbacid Model'!$M$156/(1+C$4)^3)+('Carbacid Model'!$N$156/(1+C$4)^4)+('Carbacid Model'!$O$156/(1+C$4)^5)+(('Carbacid Model'!$O$156*(1+$B5)/(C$4-$B5))/(1+C$4)^5)+'Carbacid Model'!$C$188-'Carbacid Model'!$C$189)/'Carbacid Model'!$C$191) -> 38.52082 | D5: =((('Carbacid Model'!$K$156/(1+D$4))+('Carbacid Model'!$L$156/(1+D$4)^2)+('Carbacid Model'!$M$156/(1+D$4)^3)+('Carbacid Model'!$N$156/(1+D$4)^4)+('Carbacid Model'!$O$156/(1+D$4)^5)+(('Carbacid Model'!$O$156*(1+$B5)/(D$4-$B5))/(1+D$4)^5)+'Carbacid Model'!$C$188-'Carbacid Model'!$C$189)/'Carbacid Model'!$C$191) -> 35.925421 | E5: =((('Carbacid Model'!$K$156/(1+E$4))+('Carbacid Model'!$L$156/(1+E$4)^2)+('Carbacid Model'!$M$156/(1+E$4)^3)+('Carbacid Model'!$N$156/(1+E$4)^4)+('Carbacid Model'!$O$156/(1+E$4)^5)+(('Carbacid Model'!$O$156*(1+$B5)/(E$4-$B5))/(1+E$4)^5)+'Carbacid Model'!$C$188-'Carbacid Model'!$C$189)/'Carbacid Model'!$C$191) -> 33.764854 | F5: =((('Carbacid Model'!$K$156/(1+F$4))+('Carbacid Model'!$L$156/(1+F$4)^2)+('Carbacid Model'!$M$156/(1+F$4)^3)+('Carbacid Model'!$N$156/(1+F$4)^4)+('Carbacid Model'!$O$156/(1+F$4)^5)+(('Carbacid Model'!$O$156*(1+$B5)/(F$4-$B5))/(1+F$4)^5)+'Carbacid Model'!$C$188-'Carbacid Model'!$C$189)/'Carbacid Model'!$C$191) -> 31.938698 | G5: =((('Carbacid Model'!$K$156/(1+G$4))+('Carbacid Model'!$L$156/(1+G$4)^2)+('Carbacid Model'!$M$156/(1+G$4)^3)+('Carbacid Model'!$N$156/(1+G$4)^4)+('Carbacid Model'!$O$156/(1+G$4)^5)+(('Carbacid Model'!$O$156*(1+$B5)/(G$4-$B5))/(1+G$4)^5)+'Carbacid Model'!$C$188-'Carbacid Model'!$C$189)/'Carbacid Model'!$C$191) -> 30.375228 | H5: =((('Carbacid Model'!$K$156/(1+H$4))+('Carbacid Model'!$L$156/(1+H$4)^2)+('Carbacid Model'!$M$156/(1+H$4)^3)+('Carbacid Model'!$N$156/(1+H$4)^4)+('Carbacid Model'!$O$156/(1+H$4)^5)+(('Carbacid Model'!$O$156*(1+$B5)/(H$4-$B5))/(1+H$4)^5)+'Carbacid Model'!$C$188-'Carbacid Model'!$C$189)/'Carbacid Model'!$C$191) -> 29.021847
B6: 0.04 | C6: =((('Carbacid Model'!$K$156/(1+C$4))+('Carbacid Model'!$L$156/(1+C$4)^2)+('Carbacid Model'!$M$156/(1+C$4)^3)+('Carbacid Model'!$N$156/(1+C$4)^4)+('Carbacid Model'!$O$156/(1+C$4)^5)+(('Carbacid Model'!$O$156*(1+$B6)/(C$4-$B6))/(1+C$4)^5)+'Carbacid Model'!$C$188-'Carbacid Model'!$C$189)/'Carbacid Model'!$C$191) -> 40.723967 | D6: =((('Carbacid Model'!$K$156/(1+D$4))+('Carbacid Model'!$L$156/(1+D$4)^2)+('Carbacid Model'!$M$156/(1+D$4)^3)+('Carbacid Model'!$N$156/(1+D$4)^4)+('Carbacid Model'!$O$156/(1+D$4)^5)+(('Carbacid Model'!$O$156*(1+$B6)/(D$4-$B6))/(1+D$4)^5)+'Carbacid Model'!$C$188-'Carbacid Model'!$C$189)/'Carbacid Model'!$C$191) -> 37.665574 | E6: =((('Carbacid Model'!$K$156/(1+E$4))+('Carbacid Model'!$L$156/(1+E$4)^2)+('Carbacid Model'!$M$156/(1+E$4)^3)+('Carbacid Model'!$N$156/(1+E$4)^4)+('Carbacid Model'!$O$156/(1+E$4)^5)+(('Carbacid Model'!$O$156*(1+$B6)/(E$4-$B6))/(1+E$4)^5)+'Carbacid Model'!$C$188-'Carbacid Model'!$C$189)/'Carbacid Model'!$C$191) -> 35.165197 | F6: =((('Carbacid Model'!$K$156/(1+F$4))+('Carbacid Model'!$L$156/(1+F$4)^2)+('Carbacid Model'!$M$156/(1+F$4)^3)+('Carbacid Model'!$N$156/(1+F$4)^4)+('Carbacid Model'!$O$156/(1+F$4)^5)+(('Carbacid Model'!$O$156*(1+$B6)/(F$4-$B6))/(1+F$4)^5)+'Carbacid Model'!$C$188-'Carbacid Model'!$C$189)/'Carbacid Model'!$C$191) -> 33.083271 | G6: =((('Carbacid Model'!$K$156/(1+G$4))+('Carbacid Model'!$L$156/(1+G$4)^2)+('Carbacid Model'!$M$156/(1+G$4)^3)+('Carbacid Model'!$N$156/(1+G$4)^4)+('Carbacid Model'!$O$156/(1+G$4)^5)+(('Carbacid Model'!$O$156*(1+$B6)/(G$4-$B6))/(1+G$4)^5)+'Carbacid Model'!$C$188-'Carbacid Model'!$C$189)/'Carbacid Model'!$C$191) -> 31.323177 | H6: =((('Carbacid Model'!$K$156/(1+H$4))+('Carbacid Model'!$L$156/(1+H$4)^2)+('Carbacid Model'!$M$156/(1+H$4)^3)+('Carbacid Model'!$N$156/(1+H$4)^4)+('Carbacid Model'!$O$156/(1+H$4)^5)+(('Carbacid Model'!$O$156*(1+$B6)/(H$4-$B6))/(1+H$4)^5)+'Carbacid Model'!$C$188-'Carbacid Model'!$C$189)/'Carbacid Model'!$C$191) -> 29.815906
B7: 0.05 | C7: =((('Carbacid Model'!$K$156/(1+C$4))+('Carbacid Model'!$L$156/(1+C$4)^2)+('Carbacid Model'!$M$156/(1+C$4)^3)+('Carbacid Model'!$N$156/(1+C$4)^4)+('Carbacid Model'!$O$156/(1+C$4)^5)+(('Carbacid Model'!$O$156*(1+$B7)/(C$4-$B7))/(1+C$4)^5)+'Carbacid Model'!$C$188-'Carbacid Model'!$C$189)/'Carbacid Model'!$C$191) -> 43.477901 | D7: =((('Carbacid Model'!$K$156/(1+D$4))+('Carbacid Model'!$L$156/(1+D$4)^2)+('Carbacid Model'!$M$156/(1+D$4)^3)+('Carbacid Model'!$N$156/(1+D$4)^4)+('Carbacid Model'!$O$156/(1+D$4)^5)+(('Carbacid Model'!$O$156*(1+$B7)/(D$4-$B7))/(1+D$4)^5)+'Carbacid Model'!$C$188-'Carbacid Model'!$C$189)/'Carbacid Model'!$C$191) -> 39.792429 | E7: =((('Carbacid Model'!$K$156/(1+E$4))+('Carbacid Model'!$L$156/(1+E$4)^2)+('Carbacid Model'!$M$156/(1+E$4)^3)+('Carbacid Model'!$N$156/(1+E$4)^4)+('Carbacid Model'!$O$156/(1+E$4)^5)+(('Carbacid Model'!$O$156*(1+$B7)/(E$4-$B7))/(1+E$4)^5)+'Carbacid Model'!$C$188-'Carbacid Model'!$C$189)/'Carbacid Model'!$C$191) -> 36.845609 | F7: =((('Carbacid Model'!$K$156/(1+F$4))+('Carbacid Model'!$L$156/(1+F$4)^2)+('Carbacid Model'!$M$156/(1+F$4)^3)+('Carbacid Model'!$N$156/(1+F$4)^4)+('Carbacid Model'!$O$156/(1+F$4)^5)+(('Carbacid Model'!$O$156*(1+$B7)/(F$4-$B7))/(1+F$4)^5)+'Carbacid Model'!$C$188-'Carbacid Model'!$C$189)/'Carbacid Model'!$C$191) -> 34.435947 | G7: =((('Carbacid Model'!$K$156/(1+G$4))+('Carbacid Model'!$L$156/(1+G$4)^2)+('Carbacid Model'!$M$156/(1+G$4)^3)+('Carbacid Model'!$N$156/(1+G$4)^4)+('Carbacid Model'!$O$156/(1+G$4)^5)+(('Carbacid Model'!$O$156*(1+$B7)/(G$4-$B7))/(1+G$4)^5)+'Carbacid Model'!$C$188-'Carbacid Model'!$C$189)/'Carbacid Model'!$C$191) -> 32.429118 | H7: =((('Carbacid Model'!$K$156/(1+H$4))+('Carbacid Model'!$L$156/(1+H$4)^2)+('Carbacid Model'!$M$156/(1+H$4)^3)+('Carbacid Model'!$N$156/(1+H$4)^4)+('Carbacid Model'!$O$156/(1+H$4)^5)+(('Carbacid Model'!$O$156*(1+$B7)/(H$4-$B7))/(1+H$4)^5)+'Carbacid Model'!$C$188-'Carbacid Model'!$C$189)/'Carbacid Model'!$C$191) -> 30.732127
B8: 0.06 | C8: =((('Carbacid Model'!$K$156/(1+C$4))+('Carbacid Model'!$L$156/(1+C$4)^2)+('Carbacid Model'!$M$156/(1+C$4)^3)+('Carbacid Model'!$N$156/(1+C$4)^4)+('Carbacid Model'!$O$156/(1+C$4)^5)+(('Carbacid Model'!$O$156*(1+$B8)/(C$4-$B8))/(1+C$4)^5)+'Carbacid Model'!$C$188-'Carbacid Model'!$C$189)/'Carbacid Model'!$C$191) -> 47.018673 | D8: =((('Carbacid Model'!$K$156/(1+D$4))+('Carbacid Model'!$L$156/(1+D$4)^2)+('Carbacid Model'!$M$156/(1+D$4)^3)+('Carbacid Model'!$N$156/(1+D$4)^4)+('Carbacid Model'!$O$156/(1+D$4)^5)+(('Carbacid Model'!$O$156*(1+$B8)/(D$4-$B8))/(1+D$4)^5)+'Carbacid Model'!$C$188-'Carbacid Model'!$C$189)/'Carbacid Model'!$C$191) -> 42.450998 | E8: =((('Carbacid Model'!$K$156/(1+E$4))+('Carbacid Model'!$L$156/(1+E$4)^2)+('Carbacid Model'!$M$156/(1+E$4)^3)+('Carbacid Model'!$N$156/(1+E$4)^4)+('Carbacid Model'!$O$156/(1+E$4)^5)+(('Carbacid Model'!$O$156*(1+$B8)/(E$4-$B8))/(1+E$4)^5)+'Carbacid Model'!$C$188-'Carbacid Model'!$C$189)/'Carbacid Model'!$C$191) -> 38.899445 | F8: =((('Carbacid Model'!$K$156/(1+F$4))+('Carbacid Model'!$L$156/(1+F$4)^2)+('Carbacid Model'!$M$156/(1+F$4)^3)+('Carbacid Model'!$N$156/(1+F$4)^4)+('Carbacid Model'!$O$156/(1+F$4)^5)+(('Carbacid Model'!$O$156*(1+$B8)/(F$4-$B8))/(1+F$4)^5)+'Carbacid Model'!$C$188-'Carbacid Model'!$C$189)/'Carbacid Model'!$C$191) -> 36.059158 | G8: =((('Carbacid Model'!$K$156/(1+G$4))+('Carbacid Model'!$L$156/(1+G$4)^2)+('Carbacid Model'!$M$156/(1+G$4)^3)+('Carbacid Model'!$N$156/(1+G$4)^4)+('Carbacid Model'!$O$156/(1+G$4)^5)+(('Carbacid Model'!$O$156*(1+$B8)/(G$4-$B8))/(1+G$4)^5)+'Carbacid Model'!$C$188-'Carbacid Model'!$C$189)/'Carbacid Model'!$C$191) -> 33.736138 | H8: =((('Carbacid Model'!$K$156/(1+H$4))+('Carbacid Model'!$L$156/(1+H$4)^2)+('Carbacid Model'!$M$156/(1+H$4)^3)+('Carbacid Model'!$N$156/(1+H$4)^4)+('Carbacid Model'!$O$156/(1+H$4)^5)+(('Carbacid Model'!$O$156*(1+$B8)/(H$4-$B8))/(1+H$4)^5)+'Carbacid Model'!$C$188-'Carbacid Model'!$C$189)/'Carbacid Model'!$C$191) -> 31.801052
B9: 0.07 | C9: =((('Carbacid Model'!$K$156/(1+C$4))+('Carbacid Model'!$L$156/(1+C$4)^2)+('Carbacid Model'!$M$156/(1+C$4)^3)+('Carbacid Model'!$N$156/(1+C$4)^4)+('Carbacid Model'!$O$156/(1+C$4)^5)+(('Carbacid Model'!$O$156*(1+$B9)/(C$4-$B9))/(1+C$4)^5)+'Carbacid Model'!$C$188-'Carbacid Model'!$C$189)/'Carbacid Model'!$C$191) -> 51.739702 | D9: =((('Carbacid Model'!$K$156/(1+D$4))+('Carbacid Model'!$L$156/(1+D$4)^2)+('Carbacid Model'!$M$156/(1+D$4)^3)+('Carbacid Model'!$N$156/(1+D$4)^4)+('Carbacid Model'!$O$156/(1+D$4)^5)+(('Carbacid Model'!$O$156*(1+$B9)/(D$4-$B9))/(1+D$4)^5)+'Carbacid Model'!$C$188-'Carbacid Model'!$C$189)/'Carbacid Model'!$C$191) -> 45.869157 | E9: =((('Carbacid Model'!$K$156/(1+E$4))+('Carbacid Model'!$L$156/(1+E$4)^2)+('Carbacid Model'!$M$156/(1+E$4)^3)+('Carbacid Model'!$N$156/(1+E$4)^4)+('Carbacid Model'!$O$156/(1+E$4)^5)+(('Carbacid Model'!$O$156*(1+$B9)/(E$4-$B9))/(1+E$4)^5)+'Carbacid Model'!$C$188-'Carbacid Model'!$C$189)/'Carbacid Model'!$C$191) -> 41.466741 | F9: =((('Carbacid Model'!$K$156/(1+F$4))+('Carbacid Model'!$L$156/(1+F$4)^2)+('Carbacid Model'!$M$156/(1+F$4)^3)+('Carbacid Model'!$N$156/(1+F$4)^4)+('Carbacid Model'!$O$156/(1+F$4)^5)+(('Carbacid Model'!$O$156*(1+$B9)/(F$4-$B9))/(1+F$4)^5)+'Carbacid Model'!$C$188-'Carbacid Model'!$C$189)/'Carbacid Model'!$C$191) -> 38.043084 | G9: =((('Carbacid Model'!$K$156/(1+G$4))+('Carbacid Model'!$L$156/(1+G$4)^2)+('Carbacid Model'!$M$156/(1+G$4)^3)+('Carbacid Model'!$N$156/(1+G$4)^4)+('Carbacid Model'!$O$156/(1+G$4)^5)+(('Carbacid Model'!$O$156*(1+$B9)/(G$4-$B9))/(1+G$4)^5)+'Carbacid Model'!$C$188-'Carbacid Model'!$C$189)/'Carbacid Model'!$C$191) -> 35.304563 | H9: =((('Carbacid Model'!$K$156/(1+H$4))+('Carbacid Model'!$L$156/(1+H$4)^2)+('Carbacid Model'!$M$156/(1+H$4)^3)+('Carbacid Model'!$N$156/(1+H$4)^4)+('Carbacid Model'!$O$156/(1+H$4)^5)+(('Carbacid Model'!$O$156*(1+$B9)/(H$4-$B9))/(1+H$4)^5)+'Carbacid Model'!$C$188-'Carbacid Model'!$C$189)/'Carbacid Model'!$C$191) -> 33.064326
B12: Weighted Target Sensitivity: EV/EBITDA and P/E Multiples
B13: P/E \ EV/EBITDA | C13: 5 | D13: 5.5 | E13: 6 | F13: 6.5 | G13: 7 | H13: 7.5
B14: 8 | C14: ='Carbacid Model'!$C$192*'Carbacid Model'!$C$197+((('Carbacid Model'!$O$58*C$13*'Carbacid Model'!$O$157)+'Carbacid Model'!$C$188-'Carbacid Model'!$C$189)/'Carbacid Model'!$C$191)*'Carbacid Model'!$C$198+(('Carbacid Model'!$O$66*$B14*'Carbacid Model'!$O$157)/'Carbacid Model'!$C$191)*'Carbacid Model'!$C$199 -> 31.728342 | D14: ='Carbacid Model'!$C$192*'Carbacid Model'!$C$197+((('Carbacid Model'!$O$58*D$13*'Carbacid Model'!$O$157)+'Carbacid Model'!$C$188-'Carbacid Model'!$C$189)/'Carbacid Model'!$C$191)*'Carbacid Model'!$C$198+(('Carbacid Model'!$O$66*$B14*'Carbacid Model'!$O$157)/'Carbacid Model'!$C$191)*'Carbacid Model'!$C$199 -> 31.992244 | E14: ='Carbacid Model'!$C$192*'Carbacid Model'!$C$197+((('Carbacid Model'!$O$58*E$13*'Carbacid Model'!$O$157)+'Carbacid Model'!$C$188-'Carbacid Model'!$C$189)/'Carbacid Model'!$C$191)*'Carbacid Model'!$C$198+(('Carbacid Model'!$O$66*$B14*'Carbacid Model'!$O$157)/'Carbacid Model'!$C$191)*'Carbacid Model'!$C$199 -> 32.256146 | F14: ='Carbacid Model'!$C$192*'Carbacid Model'!$C$197+((('Carbacid Model'!$O$58*F$13*'Carbacid Model'!$O$157)+'Carbacid Model'!$C$188-'Carbacid Model'!$C$189)/'Carbacid Model'!$C$191)*'Carbacid Model'!$C$198+(('Carbacid Model'!$O$66*$B14*'Carbacid Model'!$O$157)/'Carbacid Model'!$C$191)*'Carbacid Model'!$C$199 -> 32.520048 | G14: ='Carbacid Model'!$C$192*'Carbacid Model'!$C$197+((('Carbacid Model'!$O$58*G$13*'Carbacid Model'!$O$157)+'Carbacid Model'!$C$188-'Carbacid Model'!$C$189)/'Carbacid Model'!$C$191)*'Carbacid Model'!$C$198+(('Carbacid Model'!$O$66*$B14*'Carbacid Model'!$O$157)/'Carbacid Model'!$C$191)*'Carbacid Model'!$C$199 -> 32.783949 | H14: ='Carbacid Model'!$C$192*'Carbacid Model'!$C$197+((('Carbacid Model'!$O$58*H$13*'Carbacid Model'!$O$157)+'Carbacid Model'!$C$188-'Carbacid Model'!$C$189)/'Carbacid Model'!$C$191)*'Carbacid Model'!$C$198+(('Carbacid Model'!$O$66*$B14*'Carbacid Model'!$O$157)/'Carbacid Model'!$C$191)*'Carbacid Model'!$C$199 -> 33.047851
B15: 9 | C15: ='Carbacid Model'!$C$192*'Carbacid Model'!$C$197+((('Carbacid Model'!$O$58*C$13*'Carbacid Model'!$O$157)+'Carbacid Model'!$C$188-'Carbacid Model'!$C$189)/'Carbacid Model'!$C$191)*'Carbacid Model'!$C$198+(('Carbacid Model'!$O$66*$B15*'Carbacid Model'!$O$157)/'Carbacid Model'!$C$191)*'Carbacid Model'!$C$199 -> 32.028023 | D15: ='Carbacid Model'!$C$192*'Carbacid Model'!$C$197+((('Carbacid Model'!$O$58*D$13*'Carbacid Model'!$O$157)+'Carbacid Model'!$C$188-'Carbacid Model'!$C$189)/'Carbacid Model'!$C$191)*'Carbacid Model'!$C$198+(('Carbacid Model'!$O$66*$B15*'Carbacid Model'!$O$157)/'Carbacid Model'!$C$191)*'Carbacid Model'!$C$199 -> 32.291925 | E15: ='Carbacid Model'!$C$192*'Carbacid Model'!$C$197+((('Carbacid Model'!$O$58*E$13*'Carbacid Model'!$O$157)+'Carbacid Model'!$C$188-'Carbacid Model'!$C$189)/'Carbacid Model'!$C$191)*'Carbacid Model'!$C$198+(('Carbacid Model'!$O$66*$B15*'Carbacid Model'!$O$157)/'Carbacid Model'!$C$191)*'Carbacid Model'!$C$199 -> 32.555827 | F15: ='Carbacid Model'!$C$192*'Carbacid Model'!$C$197+((('Carbacid Model'!$O$58*F$13*'Carbacid Model'!$O$157)+'Carbacid Model'!$C$188-'Carbacid Model'!$C$189)/'Carbacid Model'!$C$191)*'Carbacid Model'!$C$198+(('Carbacid Model'!$O$66*$B15*'Carbacid Model'!$O$157)/'Carbacid Model'!$C$191)*'Carbacid Model'!$C$199 -> 32.819729 | G15: ='Carbacid Model'!$C$192*'Carbacid Model'!$C$197+((('Carbacid Model'!$O$58*G$13*'Carbacid Model'!$O$157)+'Carbacid Model'!$C$188-'Carbacid Model'!$C$189)/'Carbacid Model'!$C$191)*'Carbacid Model'!$C$198+(('Carbacid Model'!$O$66*$B15*'Carbacid Model'!$O$157)/'Carbacid Model'!$C$191)*'Carbacid Model'!$C$199 -> 33.083631 | H15: ='Carbacid Model'!$C$192*'Carbacid Model'!$C$197+((('Carbacid Model'!$O$58*H$13*'Carbacid Model'!$O$157)+'Carbacid Model'!$C$188-'Carbacid Model'!$C$189)/'Carbacid Model'!$C$191)*'Carbacid Model'!$C$198+(('Carbacid Model'!$O$66*$B15*'Carbacid Model'!$O$157)/'Carbacid Model'!$C$191)*'Carbacid Model'!$C$199 -> 33.347533
B16: 10 | C16: ='Carbacid Model'!$C$192*'Carbacid Model'!$C$197+((('Carbacid Model'!$O$58*C$13*'Carbacid Model'!$O$157)+'Carbacid Model'!$C$188-'Carbacid Model'!$C$189)/'Carbacid Model'!$C$191)*'Carbacid Model'!$C$198+(('Carbacid Model'!$O$66*$B16*'Carbacid Model'!$O$157)/'Carbacid Model'!$C$191)*'Carbacid Model'!$C$199 -> 32.327705 | D16: ='Carbacid Model'!$C$192*'Carbacid Model'!$C$197+((('Carbacid Model'!$O$58*D$13*'Carbacid Model'!$O$157)+'Carbacid Model'!$C$188-'Carbacid Model'!$C$189)/'Carbacid Model'!$C$191)*'Carbacid Model'!$C$198+(('Carbacid Model'!$O$66*$B16*'Carbacid Model'!$O$157)/'Carbacid Model'!$C$191)*'Carbacid Model'!$C$199 -> 32.591607 | E16: ='Carbacid Model'!$C$192*'Carbacid Model'!$C$197+((('Carbacid Model'!$O$58*E$13*'Carbacid Model'!$O$157)+'Carbacid Model'!$C$188-'Carbacid Model'!$C$189)/'Carbacid Model'!$C$191)*'Carbacid Model'!$C$198+(('Carbacid Model'!$O$66*$B16*'Carbacid Model'!$O$157)/'Carbacid Model'!$C$191)*'Carbacid Model'!$C$199 -> 32.855509 | F16: ='Carbacid Model'!$C$192*'Carbacid Model'!$C$197+((('Carbacid Model'!$O$58*F$13*'Carbacid Model'!$O$157)+'Carbacid Model'!$C$188-'Carbacid Model'!$C$189)/'Carbacid Model'!$C$191)*'Carbacid Model'!$C$198+(('Carbacid Model'!$O$66*$B16*'Carbacid Model'!$O$157)/'Carbacid Model'!$C$191)*'Carbacid Model'!$C$199 -> 33.11941 | G16: ='Carbacid Model'!$C$192*'Carbacid Model'!$C$197+((('Carbacid Model'!$O$58*G$13*'Carbacid Model'!$O$157)+'Carbacid Model'!$C$188-'Carbacid Model'!$C$189)/'Carbacid Model'!$C$191)*'Carbacid Model'!$C$198+(('Carbacid Model'!$O$66*$B16*'Carbacid Model'!$O$157)/'Carbacid Model'!$C$191)*'Carbacid Model'!$C$199 -> 33.383312 | H16: ='Carbacid Model'!$C$192*'Carbacid Model'!$C$197+((('Carbacid Model'!$O$58*H$13*'Carbacid Model'!$O$157)+'Carbacid Model'!$C$188-'Carbacid Model'!$C$189)/'Carbacid Model'!$C$191)*'Carbacid Model'!$C$198+(('Carbacid Model'!$O$66*$B16*'Carbacid Model'!$O$157)/'Carbacid Model'!$C$191)*'Carbacid Model'!$C$199 -> 33.647214
B17: 11 | C17: ='Carbacid Model'!$C$192*'Carbacid Model'!$C$197+((('Carbacid Model'!$O$58*C$13*'Carbacid Model'!$O$157)+'Carbacid Model'!$C$188-'Carbacid Model'!$C$189)/'Carbacid Model'!$C$191)*'Carbacid Model'!$C$198+(('Carbacid Model'!$O$66*$B17*'Carbacid Model'!$O$157)/'Carbacid Model'!$C$191)*'Carbacid Model'!$C$199 -> 32.627386 | D17: ='Carbacid Model'!$C$192*'Carbacid Model'!$C$197+((('Carbacid Model'!$O$58*D$13*'Carbacid Model'!$O$157)+'Carbacid Model'!$C$188-'Carbacid Model'!$C$189)/'Carbacid Model'!$C$191)*'Carbacid Model'!$C$198+(('Carbacid Model'!$O$66*$B17*'Carbacid Model'!$O$157)/'Carbacid Model'!$C$191)*'Carbacid Model'!$C$199 -> 32.891288 | E17: ='Carbacid Model'!$C$192*'Carbacid Model'!$C$197+((('Carbacid Model'!$O$58*E$13*'Carbacid Model'!$O$157)+'Carbacid Model'!$C$188-'Carbacid Model'!$C$189)/'Carbacid Model'!$C$191)*'Carbacid Model'!$C$198+(('Carbacid Model'!$O$66*$B17*'Carbacid Model'!$O$157)/'Carbacid Model'!$C$191)*'Carbacid Model'!$C$199 -> 33.15519 | F17: ='Carbacid Model'!$C$192*'Carbacid Model'!$C$197+((('Carbacid Model'!$O$58*F$13*'Carbacid Model'!$O$157)+'Carbacid Model'!$C$188-'Carbacid Model'!$C$189)/'Carbacid Model'!$C$191)*'Carbacid Model'!$C$198+(('Carbacid Model'!$O$66*$B17*'Carbacid Model'!$O$157)/'Carbacid Model'!$C$191)*'Carbacid Model'!$C$199 -> 33.419092 | G17: ='Carbacid Model'!$C$192*'Carbacid Model'!$C$197+((('Carbacid Model'!$O$58*G$13*'Carbacid Model'!$O$157)+'Carbacid Model'!$C$188-'Carbacid Model'!$C$189)/'Carbacid Model'!$C$191)*'Carbacid Model'!$C$198+(('Carbacid Model'!$O$66*$B17*'Carbacid Model'!$O$157)/'Carbacid Model'!$C$191)*'Carbacid Model'!$C$199 -> 33.682994 | H17: ='Carbacid Model'!$C$192*'Carbacid Model'!$C$197+((('Carbacid Model'!$O$58*H$13*'Carbacid Model'!$O$157)+'Carbacid Model'!$C$188-'Carbacid Model'!$C$189)/'Carbacid Model'!$C$191)*'Carbacid Model'!$C$198+(('Carbacid Model'!$O$66*$B17*'Carbacid Model'!$O$157)/'Carbacid Model'!$C$191)*'Carbacid Model'!$C$199 -> 33.946896
B18: 12 | C18: ='Carbacid Model'!$C$192*'Carbacid Model'!$C$197+((('Carbacid Model'!$O$58*C$13*'Carbacid Model'!$O$157)+'Carbacid Model'!$C$188-'Carbacid Model'!$C$189)/'Carbacid Model'!$C$191)*'Carbacid Model'!$C$198+(('Carbacid Model'!$O$66*$B18*'Carbacid Model'!$O$157)/'Carbacid Model'!$C$191)*'Carbacid Model'!$C$199 -> 32.927068 | D18: ='Carbacid Model'!$C$192*'Carbacid Model'!$C$197+((('Carbacid Model'!$O$58*D$13*'Carbacid Model'!$O$157)+'Carbacid Model'!$C$188-'Carbacid Model'!$C$189)/'Carbacid Model'!$C$191)*'Carbacid Model'!$C$198+(('Carbacid Model'!$O$66*$B18*'Carbacid Model'!$O$157)/'Carbacid Model'!$C$191)*'Carbacid Model'!$C$199 -> 33.19097 | E18: ='Carbacid Model'!$C$192*'Carbacid Model'!$C$197+((('Carbacid Model'!$O$58*E$13*'Carbacid Model'!$O$157)+'Carbacid Model'!$C$188-'Carbacid Model'!$C$189)/'Carbacid Model'!$C$191)*'Carbacid Model'!$C$198+(('Carbacid Model'!$O$66*$B18*'Carbacid Model'!$O$157)/'Carbacid Model'!$C$191)*'Carbacid Model'!$C$199 -> 33.454872 | F18: ='Carbacid Model'!$C$192*'Carbacid Model'!$C$197+((('Carbacid Model'!$O$58*F$13*'Carbacid Model'!$O$157)+'Carbacid Model'!$C$188-'Carbacid Model'!$C$189)/'Carbacid Model'!$C$191)*'Carbacid Model'!$C$198+(('Carbacid Model'!$O$66*$B18*'Carbacid Model'!$O$157)/'Carbacid Model'!$C$191)*'Carbacid Model'!$C$199 -> 33.718773 | G18: ='Carbacid Model'!$C$192*'Carbacid Model'!$C$197+((('Carbacid Model'!$O$58*G$13*'Carbacid Model'!$O$157)+'Carbacid Model'!$C$188-'Carbacid Model'!$C$189)/'Carbacid Model'!$C$191)*'Carbacid Model'!$C$198+(('Carbacid Model'!$O$66*$B18*'Carbacid Model'!$O$157)/'Carbacid Model'!$C$191)*'Carbacid Model'!$C$199 -> 33.982675 | H18: ='Carbacid Model'!$C$192*'Carbacid Model'!$C$197+((('Carbacid Model'!$O$58*H$13*'Carbacid Model'!$O$157)+'Carbacid Model'!$C$188-'Carbacid Model'!$C$189)/'Carbacid Model'!$C$191)*'Carbacid Model'!$C$198+(('Carbacid Model'!$O$66*$B18*'Carbacid Model'!$O$157)/'Carbacid Model'!$C$191)*'Carbacid Model'!$C$199 -> 34.246577
