Workbook

Sheet KPLC_MODEL
B1: Model by Brian Githinji
B3: Dashboard / Final Output
B4: Recommendation | D4: =Q308 -> BUY | F4: Current Share Price | G4: =D19 -> 18.35 | J4: Target Price | K4: =Q304 -> 56.152765 | N4: Upside / Downside | O4: =Q305 -> 2.0600962
B5: Current share price | D5: =D19 -> 18.35
B6: Target price | D6: =Q304 -> 56.152765
B7: Upside / downside | D7: =Q305 -> 2.0600962
B8: FY2026E DPS | D8: =M247 -> 0.70286511
B9: Forward dividend yield | D9: =Q306 -> 0.038303276
B10: Total return | D10: =Q307 -> 2.0983995
B11: Residual Income value | D11: =Q283 -> 54.025189
B12: FCFE value | D12: =Q288 -> 60.826951
B13: DDM value | D13: =Q292 -> 8.0111417
B14: Justified P/B value | D14: =Q295 -> 73.054245
B16: ASSUMPTIONS
B17: Core principle
B18: Control / Assumption | C18: Unit | D18: Value | S18: Notes
B19: Current share price | C19: KSh/share | D19: 18.35 | S19: Editable input only used for upside/total return.
B20: Shares outstanding | C20: mn shares | D20: ='Historical Dataset'!N266 -> 1951.4668 | S20: Formula-linked to share data.
B21: Market capitalization | C21: KSh mn | D21: =D19*D20 -> 35809.416 | S21: Current price × shares outstanding.
B22: Risk-free rate | C22: % | D22: 0.1239 | S22: Editable market input.
B23: Beta | C23: x | D23: 0.3 | S23: Low-beta regulated utility assumption; editable.
B24: Equity risk premium | C24: % | D24: 0.06 | S24: Editable ERP input.
B25: Size / liquidity premium | C25: % | D25: 0.02 | S25: NSE liquidity and small-cap premium.
B26: Regulatory / turnaround premium | C26: % | D26: 0.015 | S26: Tariff, policy and execution risk.
B27: Cost of equity | C27: % | D27: =D22+D23*D24+D25+D26 -> 0.1769 | S27: Rf + beta×ERP + size/liquidity + regulatory premium.
B28: Normalized pre-tax cost of debt | C28: % | D28: 0.055 | S28: Editable; compare against actual interest/debt.
B29: Normalized tax rate | C29: % | D29: =MIN(MAX(AVERAGE(ABS('Historical Dataset'!L124/'Historical Dataset'!L123),ABS('Historical Dataset'!M124/'Historical Dataset'!M123),ABS('Historical Dataset'!N124/'Historical Dataset'!N123)),0),30%) -> 0.29976869 | S29: Capped at 30% statutory proxy.
B30: Inflation assumption | C30: % | D30: 0.064 | S30: Editable macro input.
B31: Real GDP growth assumption | C31: % | D31: 0.045 | S31: Editable demand anchor.
B32: Terminal growth | C32: % | D32: =MIN((D30*0.6)+(D31*0.4),5.5%) -> 0.055 | S32: Long-run nominal regulated utility growth cap.
B33: Unit growth floor | C33: % | D33: =MAX(2%,D31*0.5) -> 0.0225 | S33: Electrification and GDP floor.
B34: Unit growth cap | C34: % | D34: =MIN(6%,D31+1.5%) -> 0.06 | S34: Prevents extrapolating FY2025 rebound indefinitely.
B35: Annual unit-growth fade | C35: % | D35: 0.005 | S35: Growth fades toward mature demand.
B36: Effective price growth floor | C36: % | D36: 0 | S36: Current tariffs remain in force unless reviewed.
B37: Effective price growth cap | C37: % | D37: =MIN(D30*0.5,3%) -> 0.03 | S37: Partial inflation pass-through, capped.
B38: Annual effective-price growth fade | C38: % | D38: 0.0025 | S38: Price growth fades as tariffs normalize.
B39: Distribution efficiency target | C39: % | D39: 0.82 | S39: Gradual target, not immediate full recovery.
B40: Annual efficiency improvement | C40: % | D40: =MIN(0.75%,('Historical Dataset'!N20-'Historical Dataset'!M20)/2) -> 0.0075 | S40: Half latest improvement, capped at 75bps.
B41: Thermal share floor | C41: % | D41: 0.07 | S41: Thermal dispatch does not disappear.
B42: Thermal share annual fade | C42: % | D42: 0.005 | S42: Gradual renewable integration.
...

Sheet Rev Cost Analytics
A1: Revenue & Cost Structure Analytics
A3: FY2025 income statement snapshot
A4: Metric | B4: KSh mn | C4: % / margin | D4: Formula basis
A5: Revenue from contracts with customers | B5: ='Historical Dataset'!N114 -> 219284.57 | C5: =B5/$B$5 -> 1 | D5: P&L revenue total
A6: Other income | B6: ='Historical Dataset'!N119 -> 7266.559 | C6: =B6/$B$5 -> 0.033137576 | D6: Other income / revenue
A7: Cost of sales | B7: ='Historical Dataset'!N115 -> -144663.61 | C7: =ABS(B7)/$B$5 -> 0.65970718 | D7: Cost burden / revenue
A8: Gross profit | B8: ='Historical Dataset'!N116 -> 74620.963 | C8: =B8/$B$5 -> 0.34029282 | D8: Gross profit / revenue
A9: Total net operating expenses | B9: ='Historical Dataset'!N117 -> -42421.437 | C9: =ABS(B9)/$B$5 -> 0.19345382 | D9: Opex burden / revenue
A10: Operating profit | B10: ='Historical Dataset'!N120 -> 39466.085 | C10: =B10/$B$5 -> 0.17997657 | D10: Operating profit / revenue
A11: Profit for the year | B11: ='Historical Dataset'!N125 -> 24466.525 | C11: =B11/$B$5 -> 0.11157431 | D11: Net margin
A13: IFRS revenue component contribution — % of revenue from contracts
A14: Component | B14: Unit | C14: 2018 | D14: 2019 | E14: 2020 | F14: 2021 | G14: 2022 | H14: 2023 | I14: 2024 | J14: 2025 | K14: FY2025 value | L14: CAGR 2018–2025
A15: Post-paid electricity sales | B15: KSh mn | C15: =IFERROR('Historical Dataset'!G65/'Historical Dataset'!G$71,"") -> 0.62256336 | D15: =IFERROR('Historical Dataset'!H65/'Historical Dataset'!H$71,"") -> 0.71918848 | E15: =IFERROR('Historical Dataset'!I65/'Historical Dataset'!I$71,"") -> 0.7380734 | F15: =IFERROR('Historical Dataset'!J65/'Historical Dataset'!J$71,"") -> 0.73988746 | G15: =IFERROR('Historical Dataset'!K65/'Historical Dataset'!K$71,"") -> 0.68130949 | H15: =IFERROR('Historical Dataset'!L65/'Historical Dataset'!L$71,"") -> 0.62932873 | I15: =IFERROR('Historical Dataset'!M65/'Historical Dataset'!M$71,"") -> 0.65319648 | J15: =IFERROR('Historical Dataset'!N65/'Historical Dataset'!N$71,"") -> 0.66812137 | K15: ='Historical Dataset'!N65 -> 146508.7 | L15: =IFERROR(IF(AND('Historical Dataset'!G65>0,'Historical Dataset'!N65>0),('Historical Dataset'!N65/'Historical Dataset'!G65)^(1/7)-1,""),"") -> 0.08683811
A16: Prepaid electricity sales | B16: KSh mn | C16: =IFERROR('Historical Dataset'!G66/'Historical Dataset'!G$71,"") -> 0.10384564 | D16: =IFERROR('Historical Dataset'!H66/'Historical Dataset'!H$71,"") -> 0.12524922 | E16: =IFERROR('Historical Dataset'!I66/'Historical Dataset'!I$71,"") -> 0.13370885 | F16: =IFERROR('Historical Dataset'!J66/'Historical Dataset'!J$71,"") -> 0.14278653 | G16: =IFERROR('Historical Dataset'!K66/'Historical Dataset'!K$71,"") -> 0.12498362 | H16: =IFERROR('Historical Dataset'!L66/'Historical Dataset'!L$71,"") -> 0.12657248 | I16: =IFERROR('Historical Dataset'!M66/'Historical Dataset'!M$71,"") -> 0.14839613 | J16: =IFERROR('Historical Dataset'!N66/'Historical Dataset'!N$71,"") -> 0.17131029 | K16: ='Historical Dataset'!N66 -> 37565.704 | L16: =IFERROR(IF(AND('Historical Dataset'!G66>0,'Historical Dataset'!N66>0),('Historical Dataset'!N66/'Historical Dataset'!G66)^(1/7)-1,""),"") -> 0.1556854
A17: Foreign exchange adjustment | B17: KSh mn | C17: =IFERROR('Historical Dataset'!G68/'Historical Dataset'!G$71,"") -> 0.070956522 | D17: =IFERROR('Historical Dataset'!H68/'Historical Dataset'!H$71,"") -> 0.0064569947 | E17: =IFERROR('Historical Dataset'!I68/'Historical Dataset'!I$71,"") -> 0.0069312449 | F17: =IFERROR('Historical Dataset'!J68/'Historical Dataset'!J$71,"") -> 0.043943119 | G17: =IFERROR('Historical Dataset'!K68/'Historical Dataset'!K$71,"") -> 0.046535955 | H17: =IFERROR('Historical Dataset'!L68/'Historical Dataset'!L$71,"") -> 0.073420167 | I17: =IFERROR('Historical Dataset'!M68/'Historical Dataset'!M$71,"") -> 0.10357323 | J17: =IFERROR('Historical Dataset'!N68/'Historical Dataset'!N$71,"") -> 0.0474847 | K17: ='Historical Dataset'!N68 -> 10412.662 | L17: =IFERROR(IF(AND('Historical Dataset'!G68>0,'Historical Dataset'!N68>0),('Historical Dataset'!N68/'Historical Dataset'!G68)^(1/7)-1,""),"") -> 0.015929028
A18: Fuel cost charge / fuel cost recovery | B18: KSh mn | C18: =IFERROR('Historical Dataset'!G69/'Historical Dataset'!G$71,"") -> 0.20263448 | D18: =IFERROR('Historical Dataset'!H69/'Historical Dataset'!H$71,"") -> 0.14910531 | E18: =IFERROR('Historical Dataset'!I69/'Historical Dataset'!I$71,"") -> 0.1212865 | F18: =IFERROR('Historical Dataset'!J69/'Historical Dataset'!J$71,"") -> 0.08229065 | G18: =IFERROR('Historical Dataset'!K69/'Historical Dataset'!K$71,"") -> 0.15536113 | H18: =IFERROR('Historical Dataset'!L69/'Historical Dataset'!L$71,"") -> 0.1788457 | I18: =IFERROR('Historical Dataset'!M69/'Historical Dataset'!M$71,"") -> 0.10510419 | J18: =IFERROR('Historical Dataset'!N69/'Historical Dataset'!N$71,"") -> 0.12389823 | K18: ='Historical Dataset'!N69 -> 27168.969 | L18: =IFERROR(IF(AND('Historical Dataset'!G69>0,'Historical Dataset'!N69>0),('Historical Dataset'!N69/'Historical Dataset'!G69)^(1/7)-1,""),"") -> 0.0029100711
A19: Revenue apportioned to RES | B19: KSh mn | C19: =IFERROR('Historical Dataset'!G70/'Historical Dataset'!G$71,"") -> 0 | D19: =IFERROR('Historical Dataset'!H70/'Historical Dataset'!H$71,"") -> 0 | E19: =IFERROR('Historical Dataset'!I70/'Historical Dataset'!I$71,"") -> 0 | F19: =IFERROR('Historical Dataset'!J70/'Historical Dataset'!J$71,"") -> -0.008907761 | G19: =IFERROR('Historical Dataset'!K70/'Historical Dataset'!K$71,"") -> -0.0081901961 | H19: =IFERROR('Historical Dataset'!L70/'Historical Dataset'!L$71,"") -> -0.0081670814 | I19: =IFERROR('Historical Dataset'!M70/'Historical Dataset'!M$71,"") -> -0.010270037 | J19: =IFERROR('Historical Dataset'!N70/'Historical Dataset'!N$71,"") -> -0.010814587 | K19: ='Historical Dataset'!N70 -> -2371.472 | L19: =IFERROR(IF(AND('Historical Dataset'!G70>0,'Historical Dataset'!N70>0),('Historical Dataset'!N70/'Historical Dataset'!G70)^(1/7)-1,""),"")
A20: Total revenue from contracts | B20: KSh mn | C20: =IFERROR('Historical Dataset'!G71/'Historical Dataset'!G$71,"") -> 1 | D20: =IFERROR('Historical Dataset'!H71/'Historical Dataset'!H$71,"") -> 1 | E20: =IFERROR('Historical Dataset'!I71/'Historical Dataset'!I$71,"") -> 1 | F20: =IFERROR('Historical Dataset'!J71/'Historical Dataset'!J$71,"") -> 1 | G20: =IFERROR('Historical Dataset'!K71/'Historical Dataset'!K$71,"") -> 1 | H20: =IFERROR('Historical Dataset'!L71/'Historical Dataset'!L$71,"") -> 1 | I20: =IFERROR('Historical Dataset'!M71/'Historical Dataset'!M$71,"") -> 1 | J20: =IFERROR('Historical Dataset'!N71/'Historical Dataset'!N$71,"") -> 1 | K20: ='Historical Dataset'!N71 -> 219284.57 | L20: =IFERROR(IF(AND('Historical Dataset'!G71>0,'Historical Dataset'!N71>0),('Historical Dataset'!N71/'Historical Dataset'!G71)^(1/7)-1,""),"") -> 0.075927906
A22: Tariff category revenue mix — % of tariff category total
A23: Tariff category | B23: Unit | C23: 2017 | D23: 2018 | E23: 2019 | F23: 2020 | G23: 2021 | H23: 2022 | I23: 2023 | J23: 2024 | K23: 2025 | L23: FY2025 value
A24: Domestic revenue | B24: KSh mn | C24: =IFERROR('Historical Dataset'!F72/SUM('Historical Dataset'!F$72:F$78),"") -> 0.29169381 | D24: =IFERROR('Historical Dataset'!G72/SUM('Historical Dataset'!G$72:G$78),"") -> 0.27722873 | E24: =IFERROR('Historical Dataset'!H72/SUM('Historical Dataset'!H$72:H$78),"") -> 0.26904203 | F24: =IFERROR('Historical Dataset'!I72/SUM('Historical Dataset'!I$72:I$78),"") -> 0.30639782 | G24: =IFERROR('Historical Dataset'!J72/SUM('Historical Dataset'!J$72:J$78),"") -> 0.27969629 | H24: =IFERROR('Historical Dataset'!K72/SUM('Historical Dataset'!K$72:K$78),"") -> 0.2745898 | I24: =IFERROR('Historical Dataset'!L72/SUM('Historical Dataset'!L$72:L$78),"") -> 0.28045142 | J24: =IFERROR('Historical Dataset'!M72/SUM('Historical Dataset'!M$72:M$78),"") -> 0.28394347 | K24: =IFERROR('Historical Dataset'!N72/SUM('Historical Dataset'!N$72:N$78),"") -> 0.29481143 | L24: ='Historical Dataset'!N72 -> 68189
A25: Small commercial revenue | B25: KSh mn | C25: =IFERROR('Historical Dataset'!F73/SUM('Historical Dataset'!F$72:F$78),"") -> 0.19610247 | D25: =IFERROR('Historical Dataset'!G73/SUM('Historical Dataset'!G$72:G$78),"") -> 0.19660037 | E25: =IFERROR('Historical Dataset'!H73/SUM('Historical Dataset'!H$72:H$78),"") -> 0.20375905 | F25: =IFERROR('Historical Dataset'!I73/SUM('Historical Dataset'!I$72:I$78),"") -> 0.17828089 | G25: =IFERROR('Historical Dataset'!J73/SUM('Historical Dataset'!J$72:J$78),"") -> 0.16799254 | H25: =IFERROR('Historical Dataset'!K73/SUM('Historical Dataset'!K$72:K$78),"") -> 0.17747536 | I25: =IFERROR('Historical Dataset'!L73/SUM('Historical Dataset'!L$72:L$78),"") -> 0.17110599 | J25: =IFERROR('Historical Dataset'!M73/SUM('Historical Dataset'!M$72:M$78),"") -> 0.17243956 | K25: =IFERROR('Historical Dataset'!N73/SUM('Historical Dataset'!N$72:N$78),"") -> 0.18035253 | L25: ='Historical Dataset'!N73 -> 41715
A26: Commercial & industrial revenue | B26: KSh mn | C26: =IFERROR('Historical Dataset'!F74/SUM('Historical Dataset'!F$72:F$78),"") -> 0.4268888 | D26: =IFERROR('Historical Dataset'!G74/SUM('Historical Dataset'!G$72:G$78),"") -> 0.43353313 | E26: =IFERROR('Historical Dataset'!H74/SUM('Historical Dataset'!H$72:H$78),"") -> 0.44395479 | F26: =IFERROR('Historical Dataset'!I74/SUM('Historical Dataset'!I$72:I$78),"") -> 0.43827531 | G26: =IFERROR('Historical Dataset'!J74/SUM('Historical Dataset'!J$72:J$78),"") -> 0.47826706 | H26: =IFERROR('Historical Dataset'!K74/SUM('Historical Dataset'!K$72:K$78),"") -> 0.47801435 | I26: =IFERROR('Historical Dataset'!L74/SUM('Historical Dataset'!L$72:L$78),"") -> 0.47971216 | J26: =IFERROR('Historical Dataset'!M74/SUM('Historical Dataset'!M$72:M$78),"") -> 0.48323151 | K26: =IFERROR('Historical Dataset'!N74/SUM('Historical Dataset'!N$72:N$78),"") -> 0.46041669 | L26: ='Historical Dataset'!N74 -> 106493
A27: Street lighting revenue | B27: KSh mn | C27: =IFERROR('Historical Dataset'!F75/SUM('Historical Dataset'!F$72:F$78),"") -> 0.003172584 | D27: =IFERROR('Historical Dataset'!G75/SUM('Historical Dataset'!G$72:G$78),"") -> 0.0033792395 | E27: =IFERROR('Historical Dataset'!H75/SUM('Historical Dataset'!H$72:H$78),"") -> 0.0045737005 | F27: =IFERROR('Historical Dataset'!I75/SUM('Historical Dataset'!I$72:I$78),"") -> 0.0053443103 | G27: =IFERROR('Historical Dataset'!J75/SUM('Historical Dataset'!J$72:J$78),"") -> 0.0053142942 | H27: =IFERROR('Historical Dataset'!K75/SUM('Historical Dataset'!K$72:K$78),"") -> 0.0054971561 | I27: =IFERROR('Historical Dataset'!L75/SUM('Historical Dataset'!L$72:L$78),"") -> 0.0046596902 | J27: =IFERROR('Historical Dataset'!M75/SUM('Historical Dataset'!M$72:M$78),"") -> 0.0054115754 | K27: =IFERROR('Historical Dataset'!N75/SUM('Historical Dataset'!N$72:N$78),"") -> 0.0070904508 | L27: ='Historical Dataset'!N75 -> 1640
A28: E-mobility revenue | B28: KSh mn | C28: =IFERROR('Historical Dataset'!F76/SUM('Historical Dataset'!F$72:F$78),"") -> 0 | D28: =IFERROR('Historical Dataset'!G76/SUM('Historical Dataset'!G$72:G$78),"") -> 0 | E28: =IFERROR('Historical Dataset'!H76/SUM('Historical Dataset'!H$72:H$78),"") -> 0 | F28: =IFERROR('Historical Dataset'!I76/SUM('Historical Dataset'!I$72:I$78),"") -> 0 | G28: =IFERROR('Historical Dataset'!J76/SUM('Historical Dataset'!J$72:J$78),"") -> 0 | H28: =IFERROR('Historical Dataset'!K76/SUM('Historical Dataset'!K$72:K$78),"") -> 0 | I28: =IFERROR('Historical Dataset'!L76/SUM('Historical Dataset'!L$72:L$78),"") -> 0 | J28: =IFERROR('Historical Dataset'!M76/SUM('Historical Dataset'!M$72:M$78),"") -> 9.8541585e-05 | K28: =IFERROR('Historical Dataset'!N76/SUM('Historical Dataset'!N$72:N$78),"") -> 0.00036749288 | L28: ='Historical Dataset'!N76 -> 85
A29: Export revenue | B29: KSh mn | C29: =IFERROR('Historical Dataset'!F77/SUM('Historical Dataset'!F$72:F$78),"") -> 0.0026284935 | D29: =IFERROR('Historical Dataset'!G77/SUM('Historical Dataset'!G$72:G$78),"") -> 0.002985966 | E29: =IFERROR('Historical Dataset'!H77/SUM('Historical Dataset'!H$72:H$78),"") -> 0.0037951983 | F29: =IFERROR('Historical Dataset'!I77/SUM('Historical Dataset'!I$72:I$78),"") -> 0.0014372427 | G29: =IFERROR('Historical Dataset'!J77/SUM('Historical Dataset'!J$72:J$78),"") -> 0.0016117652 | H29: =IFERROR('Historical Dataset'!K77/SUM('Historical Dataset'!K$72:K$78),"") -> 0.0015842292 | I29: =IFERROR('Historical Dataset'!L77/SUM('Historical Dataset'!L$72:L$78),"") -> 0.0027623902 | J29: =IFERROR('Historical Dataset'!M77/SUM('Historical Dataset'!M$72:M$78),"") -> 0.0038431218 | K29: =IFERROR('Historical Dataset'!N77/SUM('Historical Dataset'!N$72:N$78),"") -> 0.0050238438 | L29: ='Historical Dataset'!N77 -> 1162
A30: REP revenue | B30: KSh mn | C30: =IFERROR('Historical Dataset'!F78/SUM('Historical Dataset'!F$72:F$78),"") -> 0.079513844 | D30: =IFERROR('Historical Dataset'!G78/SUM('Historical Dataset'!G$72:G$78),"") -> 0.086272568 | E30: =IFERROR('Historical Dataset'!H78/SUM('Historical Dataset'!H$72:H$78),"") -> 0.074875231 | F30: =IFERROR('Historical Dataset'!I78/SUM('Historical Dataset'!I$72:I$78),"") -> 0.070264425 | G30: =IFERROR('Historical Dataset'!J78/SUM('Historical Dataset'!J$72:J$78),"") -> 0.067118047 | H30: =IFERROR('Historical Dataset'!K78/SUM('Historical Dataset'!K$72:K$78),"") -> 0.062839105 | I30: =IFERROR('Historical Dataset'!L78/SUM('Historical Dataset'!L$72:L$78),"") -> 0.061308351 | J30: =IFERROR('Historical Dataset'!M78/SUM('Historical Dataset'!M$72:M$78),"") -> 0.051032223 | K30: =IFERROR('Historical Dataset'!N78/SUM('Historical Dataset'!N$72:N$78),"") -> 0.051937552 | L30: ='Historical Dataset'!N78 -> 12013
A31: Total tariff category revenue | B31: KSh mn | C31: =IFERROR(SUM('Historical Dataset'!F$72:F$78)/SUM('Historical Dataset'!F$72:F$78),"") -> 1 | D31: =IFERROR(SUM('Historical Dataset'!G$72:G$78)/SUM('Historical Dataset'!G$72:G$78),"") -> 1 | E31: =IFERROR(SUM('Historical Dataset'!H$72:H$78)/SUM('Historical Dataset'!H$72:H$78),"") -> 1 | F31: =IFERROR(SUM('Historical Dataset'!I$72:I$78)/SUM('Historical Dataset'!I$72:I$78),"") -> 1 | G31: =IFERROR(SUM('Historical Dataset'!J$72:J$78)/SUM('Historical Dataset'!J$72:J$78),"") -> 1 | H31: =IFERROR(SUM('Historical Dataset'!K$72:K$78)/SUM('Historical Dataset'!K$72:K$78),"") -> 1 | I31: =IFERROR(SUM('Historical Dataset'!L$72:L$78)/SUM('Historical Dataset'!L$72:L$78),"") -> 1 | J31: =IFERROR(SUM('Historical Dataset'!M$72:M$78)/SUM('Historical Dataset'!M$72:M$78),"") -> 1 | K31: =IFERROR(SUM('Historical Dataset'!N$72:N$78)/SUM('Historical Dataset'!N$72:N$78),"") -> 1 | L31: =SUM('Historical Dataset'!N$72:N$78) -> 231297
A33: Cost of sales structure — % contribution to total cost of sales
A34: Cost component | B34: Unit | C34: 2018 | D34: 2019 | E34: 2020 | F34: 2021 | G34: 2022 | H34: 2023 | I34: 2024 | J34: 2025 | K34: FY2025 value | L34: FY2025 % of revenue
A35: Renewable/non-fuel energy cost | B35: KSh mn | C35: =IFERROR('Historical Dataset'!G90/'Historical Dataset'!G$95,"") -> 0.62776136 | D35: =IFERROR('Historical Dataset'!H90/'Historical Dataset'!H$95,"") -> 0.78620334 | E35: =IFERROR('Historical Dataset'!I90/'Historical Dataset'!I$95,"") -> 0.850806 | F35: =IFERROR('Historical Dataset'!J90/'Historical Dataset'!J$95,"") -> 0.80701854 | G35: =IFERROR('Historical Dataset'!K90/'Historical Dataset'!K$95,"") -> 0.68732376 | H35: =IFERROR('Historical Dataset'!L90/'Historical Dataset'!L$95,"") -> 0.65074398 | I35: =IFERROR('Historical Dataset'!M90/'Historical Dataset'!M$95,"") -> 0.70625711 | J35: =IFERROR('Historical Dataset'!N90/'Historical Dataset'!N$95,"") -> 0.69147454 | K35: ='Historical Dataset'!N90 -> -100031.2 | L35: =IFERROR(ABS(K35)/'Historical Dataset'!N$71,"") -> 0.45617072
A36: Foreign exchange costs on power purchases | B36: KSh mn | C36: =IFERROR('Historical Dataset'!G91/'Historical Dataset'!G$95,"") -> 0.091726755 | D36: =IFERROR('Historical Dataset'!H91/'Historical Dataset'!H$95,"") -> 0.010933765 | E36: =IFERROR('Historical Dataset'!I91/'Historical Dataset'!I$95,"") -> 0.022787381 | F36: =IFERROR('Historical Dataset'!J91/'Historical Dataset'!J$95,"") -> 0.074278529 | G36: =IFERROR('Historical Dataset'!K91/'Historical Dataset'!K$95,"") -> 0.077314433 | H36: =IFERROR('Historical Dataset'!L91/'Historical Dataset'!L$95,"") -> 0.11131724 | I36: =IFERROR('Historical Dataset'!M91/'Historical Dataset'!M$95,"") -> 0 | J36: =IFERROR('Historical Dataset'!N91/'Historical Dataset'!N$95,"") -> 0 | K36: ='Historical Dataset'!N91 -> 0 | L36: =IFERROR(ABS(K36)/'Historical Dataset'!N$71,"") -> 0
A37: Unrealised foreign exchange costs | B37: KSh mn | C37: =IFERROR('Historical Dataset'!G92/'Historical Dataset'!G$95,"") -> 0 | D37: =IFERROR('Historical Dataset'!H92/'Historical Dataset'!H$95,"") -> 0 | E37: =IFERROR('Historical Dataset'!I92/'Historical Dataset'!I$95,"") -> 0 | F37: =IFERROR('Historical Dataset'!J92/'Historical Dataset'!J$95,"") -> 0 | G37: =IFERROR('Historical Dataset'!K92/'Historical Dataset'!K$95,"") -> 0.0095742046 | H37: =IFERROR('Historical Dataset'!L92/'Historical Dataset'!L$95,"") -> 0.03704026 | I37: =IFERROR('Historical Dataset'!M92/'Historical Dataset'!M$95,"") -> 0.001855817 | J37: =IFERROR('Historical Dataset'!N92/'Historical Dataset'!N$95,"") -> 0.0028763973 | K37: ='Historical Dataset'!N92 -> -416.11 | L37: =IFERROR(ABS(K37)/'Historical Dataset'!N$71,"") -> 0.00189758
A38: Fuel / thermal energy cost | B38: KSh mn | C38: =IFERROR('Historical Dataset'!G93/'Historical Dataset'!G$95,"") -> 0.28051189 | D38: =IFERROR('Historical Dataset'!H93/'Historical Dataset'!H$95,"") -> 0.2028629 | E38: =IFERROR('Historical Dataset'!I93/'Historical Dataset'!I$95,"") -> 0.12640662 | F38: =IFERROR('Historical Dataset'!J93/'Historical Dataset'!J$95,"") -> 0.11870293 | G38: =IFERROR('Historical Dataset'!K93/'Historical Dataset'!K$95,"") -> 0.22577641 | H38: =IFERROR('Historical Dataset'!L93/'Historical Dataset'!L$95,"") -> 0.19567061 | I38: =IFERROR('Historical Dataset'!M93/'Historical Dataset'!M$95,"") -> 0.29053822 | J38: =IFERROR('Historical Dataset'!N93/'Historical Dataset'!N$95,"") -> 0.30552387 | K38: ='Historical Dataset'!N93 -> -44198.185 | L38: =IFERROR(ABS(K38)/'Historical Dataset'!N$71,"") -> 0.20155629
A39: Other power purchase costs | B39: KSh mn | C39: =IFERROR('Historical Dataset'!G94/'Historical Dataset'!G$95,"") -> 0 | D39: =IFERROR('Historical Dataset'!H94/'Historical Dataset'!H$95,"") -> 0 | E39: =IFERROR('Historical Dataset'!I94/'Historical Dataset'!I$95,"") -> 0 | F39: =IFERROR('Historical Dataset'!J94/'Historical Dataset'!J$95,"") -> 0 | G39: =IFERROR('Historical Dataset'!K94/'Historical Dataset'!K$95,"") -> 1.1197591e-05 | H39: =IFERROR('Historical Dataset'!L94/'Historical Dataset'!L$95,"") -> 0.0052279034 | I39: =IFERROR('Historical Dataset'!M94/'Historical Dataset'!M$95,"") -> 0.0013488581 | J39: =IFERROR('Historical Dataset'!N94/'Historical Dataset'!N$95,"") -> 0.00012519389 | K39: ='Historical Dataset'!N94 -> -18.111 | L39: =IFERROR(ABS(K39)/'Historical Dataset'!N$71,"") -> 8.2591311e-05
A40: Total cost of sales | B40: KSh mn | C40: =IFERROR('Historical Dataset'!G95/'Historical Dataset'!G$95,"") -> 1 | D40: =IFERROR('Historical Dataset'!H95/'Historical Dataset'!H$95,"") -> 1 | E40: =IFERROR('Historical Dataset'!I95/'Historical Dataset'!I$95,"") -> 1 | F40: =IFERROR('Historical Dataset'!J95/'Historical Dataset'!J$95,"") -> 1 | G40: =IFERROR('Historical Dataset'!K95/'Historical Dataset'!K$95,"") -> 1 | H40: =IFERROR('Historical Dataset'!L95/'Historical Dataset'!L$95,"") -> 1 | I40: =IFERROR('Historical Dataset'!M95/'Historical Dataset'!M$95,"") -> 1 | J40: =IFERROR('Historical Dataset'!N95/'Historical Dataset'!N$95,"") -> 1 | K40: ='Historical Dataset'!N95 -> -144663.61 | L40: =IFERROR(ABS(K40)/'Historical Dataset'!N$71,"") -> 0.65970718
A42: Operating expense structure — signed % contribution to total net operating expenses
A43: Operating expense | B43: Unit | C43: 2018 | D43: 2019 | E43: 2020 | F43: 2021 | G43: 2022 | H43: 2023 | I43: 2024 | J43: 2025 | K43: FY2025 value | L43: FY2025 impact / revenue
A44: Network management | B44: KSh mn | C44: =IFERROR('Historical Dataset'!G106/'Historical Dataset'!G$110,"") -> 0.25398841 | D44: =IFERROR('Historical Dataset'!H106/'Historical Dataset'!H$110,"") -> 0.26327081 | E44: =IFERROR('Historical Dataset'!I106/'Historical Dataset'!I$110,"") -> 0.23244242 | F44: =IFERROR('Historical Dataset'!J106/'Historical Dataset'!J$110,"") -> 0.25682854 | G44: =IFERROR('Historical Dataset'!K106/'Historical Dataset'!K$110,"") -> 0.56038907 | H44: =IFERROR('Historical Dataset'!L106/'Historical Dataset'!L$110,"") -> 0.55427543 | I44: =IFERROR('Historical Dataset'!M106/'Historical Dataset'!M$110,"") -> 0.49641191 | J44: =IFERROR('Historical Dataset'!N106/'Historical Dataset'!N$110,"") -> 0.57395795 | K44: ='Historical Dataset'!N106 -> -24348.121 | L44: =IFERROR(K44/'Historical Dataset'!N$71,"") -> -0.11103436
A45: Commercial services | B45: KSh mn | C45: =IFERROR('Historical Dataset'!G107/'Historical Dataset'!G$110,"") -> 0.34615654 | D45: =IFERROR('Historical Dataset'!H107/'Historical Dataset'!H$110,"") -> 0.18697601 | E45: =IFERROR('Historical Dataset'!I107/'Historical Dataset'!I$110,"") -> 0.13921791 | F45: =IFERROR('Historical Dataset'!J107/'Historical Dataset'!J$110,"") -> 0.14463591 | G45: =IFERROR('Historical Dataset'!K107/'Historical Dataset'!K$110,"") -> 0.13232188 | H45: =IFERROR('Historical Dataset'!L107/'Historical Dataset'!L$110,"") -> 0.079846511 | I45: =IFERROR('Historical Dataset'!M107/'Historical Dataset'!M$110,"") -> 0.12870528 | J45: =IFERROR('Historical Dataset'!N107/'Historical Dataset'!N$110,"") -> 0.14421991 | K45: ='Historical Dataset'!N107 -> -6118.016 | L45: =IFERROR(K45/'Historical Dataset'!N$71,"") -> -0.027899893
...

Sheet Historical Dataset
B1: Fahamisha Investing Model by Brian Githinji
D3: Company name | E3: Kenya Power Lightning & Co | F3: Ticker | G3: KPLC
D4: Share price | E4: 18.35 | F4: Share price date | G4: 46210
D5: Financial Year - Last year ended | E5: 45838 | F5: Model date | G5: 46212
D6: Shares Outstanding (Millions) | E6: 35809.4
F9: 43100 | G9: =EOMONTH(F9,12) -> 43465 | H9: =EOMONTH(G9,12) -> 43830 | I9: =EOMONTH(H9,12) -> 44196 | J9: =EOMONTH(I9,12) -> 44561 | K9: =EOMONTH(J9,12) -> 44926 | L9: =EOMONTH(K9,12) -> 45291 | M9: =EOMONTH(L9,12) -> 45657 | N9: =EOMONTH(M9,12) -> 46022
B10: Section | C10: Sub-section | D10: Line item | E10: Unit | F10: 2017 | G10: 2018 | H10: 2019 | I10: 2020 | J10: 2021 | K10: 2022 | L10: 2023 | M10: 2024 | N10: 2025
C11: Ownership | D11: Government of Kenya ordinary shareholding | E11: % | F11: 0.501 | G11: 0.501 | H11: 0.501 | I11: 0.501 | J11: 0.501 | K11: 0.501 | L11: 0.501 | M11: 0.501 | N11: 0.501
B12: Key operating KPIs | C12: Units, losses, efficiency, demand
B13: D. Key operating KPIs | C13: Energy demand | D13: Energy purchased - system total | E13: GWh | F13: 10204 | G13: 10702 | H13: 11493 | I13: 11462 | J13: 12101 | K13: 12653 | L13: 13290 | M13: 13684 | N13: 14472
D14: Growth Rate | G14: =G13/F13-1 -> 0.04880439 | H14: =H13/G13-1 -> 0.073911418 | I14: =I13/H13-1 -> -0.002697294 | J14: =J13/I13-1 -> 0.055749433 | K14: =K13/J13-1 -> 0.045616065 | L14: =L13/K13-1 -> 0.050343792 | M14: =M13/L13-1 -> 0.029646351 | N14: =N13/M13-1 -> 0.057585501
B15: D. Key operating KPIs | C15: Energy demand | D15: Total sales | E15: GWh | F15: 8272 | G15: 8459 | H15: 8769 | I15: 8773 | J15: 9203 | K15: 9813 | L15: 10233 | M15: 10516 | N15: 11403
D16: Growth Rate | G16: =G15/F15-1 -> 0.022606383 | H16: =H15/G15-1 -> 0.036647358 | I16: =I15/H15-1 -> 0.00045615235 | J16: =J15/I15-1 -> 0.04901402 | K16: =K15/J15-1 -> 0.066282734 | L16: =L15/K15-1 -> 0.042800367 | M16: =M15/L15-1 -> 0.027655624 | N16: =N15/M15-1 -> 0.084347661
B18: D. Key operating KPIs | C18: Efficiency | D18: System losses | E18: GWh | F18: 1932 | G18: 2244 | H18: 2724 | I18: 2689 | J18: 2898 | K18: 2839 | L18: 3057 | M18: 3169 | N18: 3069
D19: Growth Rate | G19: =G18/F18-1 -> 0.16149068 | H19: =H18/G18-1 -> 0.21390374 | I19: =I18/H18-1 -> -0.012848752 | J19: =J18/I18-1 -> 0.077724061 | K19: =K18/J18-1 -> -0.020358868 | L19: =L18/K18-1 -> 0.076787601 | M19: =M18/L18-1 -> 0.036637226 | N19: =N18/M18-1 -> -0.031555696
B20: D. Key operating KPIs | C20: Efficiency | D20: Distribution efficiency / sales % of energy purchased | E20: % | F20: =F15/F13 -> 0.81066249 | G20: =G15/G13 -> 0.79041301 | H20: =H15/H13 -> 0.76298617 | I20: =I15/I13 -> 0.76539871 | J20: =J15/J13 -> 0.76051566 | K20: =K15/K13 -> 0.7755473 | L20: =L15/L13 -> 0.76997743 | M20: =M15/M13 -> 0.76848875 | N20: =N15/N13 -> 0.78793532
B21: D. Key operating KPIs | C21: Efficiency | D21: System losses as % of energy purchased | E21: % | F21: =1-F20 -> 0.18933751 | G21: =1-G20 -> 0.20958699 | H21: =1-H20 -> 0.23701383 | I21: =1-I20 -> 0.23460129 | J21: =1-J20 -> 0.23948434 | K21: =1-K20 -> 0.2244527 | L21: =1-L20 -> 0.23002257 | M21: =1-M20 -> 0.23151125 | N21: =1-N20 -> 0.21206468
B22: D. Key operating KPIs | C22: Demand | D22: System peak demand | E22: MW | F22: 1656 | G22: 1802 | H22: 1882 | I22: 1926 | J22: 1994 | K22: 2057 | L22: 2149 | M22: 2177 | N22: 2316
D23: Growth Rate | G23: =G22/F22-1 -> 0.088164251 | H23: =H22/G22-1 -> 0.044395117 | I23: =I22/H22-1 -> 0.023379384 | J23: =J22/I22-1 -> 0.035306334 | K23: =K22/J22-1 -> 0.031594784 | L23: =L22/K22-1 -> 0.044725328 | M23: =M22/L22-1 -> 0.013029316 | N23: =N22/M22-1 -> 0.063849334
B24: D. Key operating KPIs | C24: Demand | D24: System load factor | E24: % | F24: 0.703 | G24: 0.678 | H24: 0.697 | I24: 0.679 | J24: 0.693 | K24: 0.702 | L24: 0.706 | M24: 0.718 | N24: 0.713
B25: D. Key operating KPIs | C25: Tariff/revenue | D25: Average yield of units sold | E25: cents/kWh | F25: 1564.63 | G25: 1661.97 | H25: 1629.03 | I25: 1630.87 | J25: 1681.48 | K25: 1717.27 | L25: 1996.18 | M25: 2345.24 | N25: 2041.38
D26: Growth Rate | G26: =G25/F25-1 -> 0.062212792 | H26: =H25/G25-1 -> -0.019819852 | I26: =I25/H25-1 -> 0.0011295065 | J26: =J25/I25-1 -> 0.031032516 | K26: =K25/J25-1 -> 0.021284821 | L26: =L25/K25-1 -> 0.16241476 | M26: =M25/L25-1 -> 0.17486399 | N26: =N25/M25-1 -> -0.12956456
B27: D. Key operating KPIs | C27: Cost/revenue | D27: Average cost of units sold | E27: cents/kWh | F27: 1493.09 | G27: 1627.34 | H27: 1607.31 | I27: 1656.27 | J27: 1564.35 | K27: 1675.24 | L27: 1890.43 | M27: 1835.184 | N27: 1683.647
D28: Growth Rate | G28: =G27/F27-1 -> 0.089914205 | H28: =H27/G27-1 -> -0.01230843 | I28: =I27/H27-1 -> 0.030460832 | J28: =J27/I27-1 -> -0.055498198 | K28: =K27/J27-1 -> 0.070885671 | L28: =L27/K27-1 -> 0.12845324 | M28: =M27/L27-1 -> -0.029224039 | N28: =N27/M27-1 -> -0.082573192
B29: E. Unit sales and customer metrics | C29: Customer mix and sales mix
B30: E. Unit sales and customer metrics | C30: Unit sales | D30: KPLC system sales | E30: GWh | F30: 7701 | G30: 7881 | H30: 8147 | I30: 8154 | J30: 8553 | K30: 9147 | L30: 9539 | M30: 9813 | N30: 10570
D31: Growth Rate | G31: =G30/F30-1 -> 0.023373588 | H31: =H30/G30-1 -> 0.033752062 | I31: =I30/H30-1 -> 0.00085921198 | J31: =J30/I30-1 -> 0.048933039 | K31: =K30/J30-1 -> 0.069449316 | L31: =L30/K30-1 -> 0.042855581 | M31: =M30/L30-1 -> 0.028724185 | N31: =N30/M30-1 -> 0.077142566
D32: % of total sales | F32: =F30/F15 -> 0.93097195 | G32: =G30/G15 -> 0.93167041 | H32: =H30/H15 -> 0.92906831 | I32: =I30/I15 -> 0.92944261 | J32: =J30/J15 -> 0.92937086 | K32: =K30/K15 -> 0.93213085 | L32: =L30/L15 -> 0.9321802 | M32: =M30/M15 -> 0.93314949 | N32: =N30/N15 -> 0.92694905
B33: E. Unit sales and customer metrics | C33: Unit sales | D33: REP system sales | E33: GWh | F33: 549 | G33: 554 | H33: 595 | I33: 603 | J33: 632 | K33: 650 | L33: 667 | M33: 660 | N33: 760
D34: Growth Rate | G34: =G33/F33-1 -> 0.0091074681 | H34: =H33/G33-1 -> 0.07400722 | I34: =I33/H33-1 -> 0.013445378 | J34: =J33/I33-1 -> 0.048092869 | K34: =K33/J33-1 -> 0.028481013 | L34: =L33/K33-1 -> 0.026153846 | M34: =M33/L33-1 -> -0.010494753 | N34: =N33/M33-1 -> 0.15151515
D35: % of total sales | F35: =F33/$F$15 -> 0.066368472 | G35: =G33/$G$15 -> 0.065492375 | H35: =H33/$H$15 -> 0.067852663 | I35: =I33/$I$15 -> 0.068733614 | J35: =J33/$J$15 -> 0.068673259 | K35: =K33/$K$15 -> 0.066238663 | L35: =L33/$L$15 -> 0.065181276 | M35: =M33/$M$15 -> 0.062761506 | N35: =N33/$N$15 -> 0.066649127
B36: E. Unit sales and customer metrics | C36: Unit sales | D36: Export sales | E36: GWh | F36: 22 | G36: 23 | H36: 27 | I36: 18 | J36: 17 | K36: 16 | L36: 27 | M36: 43 | N36: 73
D37: Growth Rate | G37: =G36/F36-1 -> 0.045454545 | H37: =H36/G36-1 -> 0.17391304 | I37: =I36/H36-1 -> -0.33333333 | J37: =J36/I36-1 -> -0.055555556 | K37: =K36/J36-1 -> -0.058823529 | L37: =L36/K36-1 -> 0.6875 | M37: =M36/L36-1 -> 0.59259259 | N37: =N36/M36-1 -> 0.69767442
D38: % of total sales | F38: =F36/$F$15 -> 0.0026595745 | G38: =G36/$G$15 -> 0.0027189975 | H38: =H36/$H$15 -> 0.0030790284 | I38: =I36/$I$15 -> 0.0020517497 | J38: =J36/$J$15 -> 0.0018472237 | K38: =K36/$K$15 -> 0.0016304902 | L38: =L36/$L$15 -> 0.0026385224 | M38: =M36/$M$15 -> 0.0040890072 | N38: =N36/$N$15 -> 0.0064018241
B39: E. Unit sales and customer metrics | C39: Customer category | D39: Domestic sales | E39: GWh | F39: 2138 | G39: 2335 | H39: 2366 | I39: 2508 | J39: 2630 | K39: 2728 | L39: 2798 | M39: 2769 | N39: 3104
D40: Growth Rate | G40: =G39/F39-1 -> 0.092142189 | H40: =H39/G39-1 -> 0.013276231 | I40: =I39/H39-1 -> 0.060016906 | J40: =J39/I39-1 -> 0.048644338 | K40: =K39/J39-1 -> 0.037262357 | L40: =L39/K39-1 -> 0.025659824 | M40: =M39/L39-1 -> -0.010364546 | N40: =N39/M39-1 -> 0.1209823
D41: % of total sales | F41: =F39/$F$15 -> 0.25846228 | G41: =G39/$G$15 -> 0.27603736 | H41: =H39/$H$15 -> 0.26981412 | I41: =I39/$I$15 -> 0.28587712 | J41: =J39/$J$15 -> 0.28577638 | K41: =K39/$K$15 -> 0.27799857 | L41: =L39/$L$15 -> 0.2734291 | M41: =M39/$M$15 -> 0.26331305 | N41: =N39/$N$15 -> 0.27220907
B42: E. Unit sales and customer metrics | C42: Customer category | D42: Small commercial sales | E42: GWh | F42: 1201 | G42: 1222 | H42: 1250 | I42: 1262 | J42: 1326 | K42: 1474 | L42: 1504 | M42: 1526 | N42: 1710
D43: Growth Rate | G43: =G42/F42-1 -> 0.017485429 | H43: =H42/G42-1 -> 0.022913257 | I43: =I42/H42-1 -> 0.0096 | J43: =J42/I42-1 -> 0.050713154 | K43: =K42/J42-1 -> 0.11161388 | L43: =L42/K42-1 -> 0.020352782 | M43: =M42/L42-1 -> 0.01462766 | N43: =N42/M42-1 -> 0.12057667
D44: % of total sales | F44: =F42/$F$15 -> 0.14518859 | G44: =G42/$G$15 -> 0.14446152 | H44: =H42/$H$15 -> 0.14254761 | I44: =I42/$I$15 -> 0.14385045 | J44: =J42/$J$15 -> 0.14408345 | K44: =K42/$K$15 -> 0.15020891 | L44: =L42/$L$15 -> 0.14697547 | M44: =M42/$M$15 -> 0.14511221 | N44: =N42/$N$15 -> 0.14996054
...
